Workbook

Sheet Global
A1: Parameter | B1: Value | C1: Comments
A2: Environment | B2: UAT
A3: ResultFileLocation | B3: ="L:\Regression\Test Results\Temp_Results\AEM Regression\Travelex\"&B2&"\"&B9&""&TEXT(NOW(),"ddmmmyyhhmmss")&"\" -> L:\Regression\Test Results\Temp_Results\AEM Regression\Travelex\UAT\Travel EX Migration_AEM Regression_UAT01Sep26101238\ | C3: =SUBSTITUTE(RIGHT(B3,7),"\","") -> 101238
A4: ResultFilename | B4: =B9&"_"&DAY(NOW())&TEXT(MONTH(NOW()),"MMM")&YEAR(NOW())&MINUTE(NOW())&SECOND(NOW())&".xlsx" -> Travel EX Migration_AEM Regression_UAT_1Jan20261238.xlsx | C4: =TEXT(NOW(),"YYMMDDHHMM") -> 2609011012
A5: isHTMLParsing | B5: N | C5: Default is False. XML parsing will be used for default
A6: removeNamespacesInResponse | B6: N | C6: Default is False
A7: sendOutlookMail | B7: N | C7: Default is True
A8: CreateHtmlReport | B8: Y | C8: Used for reporting. If this parameter is missing or blank, default behavior is True (html report will be generated)
A9: ResultTitle | B9: ="Travel EX Migration_AEM Regression_"&B2 -> Travel EX Migration_AEM Regression_UAT | C9: Used for reporting. If this parameter is missing or blank, default value is used "Test Run Result".
A10: Notes | B10: 01 | C10: Used for reporting. If this parameter is missing or blank, default value is used "N/A".
A11: TC_Name_Column | B11: DT_Scenario | C11: Used for reporting. This is required. If this is missing, result summary table of the report will be empty.
A12: TC_ID_Column | B12: TCID
A13: EmailSubject | B13: ="Automated Test Result - " & B9 & "-" & B2 -> Automated Test Result - Travel EX Migration_AEM Regression_UAT-UAT
A14: SendEmailTO | B14: qa@travelguard.com
A15: SendEmailCC
A16: EmailRunTimeDatasheet | B16: N
A17: QuitBreakOnFailure | B17: N
A18: PauseOnFail | B18: N
A19: Application | B19: NA
A20: WorkItemNumber | B20: NA
A21: WorkItemDescription | B21: NA
A22: Cycle | B22: 1
A23: isOfficial | B23: N
A24: ManualTestHours | B24: 1
A25: HeadlessMode | B25: N

Sheet DataSheets
A1: SheetsToExecute | B1: blnExecute | C1: ParameterSheet | D1: Comments
A2: Owner_AZ | B2: N | C2: Params_1 | D2: Comprehensive Coverage - Owner Advantange Plan | E2: w/ captcha
A3: Owner_CRVD | B3: Y | C3: Params_2 | D3: Comprehensive Coverage - Rental Car Damage Plan | E3: w/ captcha
A4: Owner_RVD | B4: N | C4: Params_3 | D4: Rental Car Coverage - Rental Car Damage Plan | E4: w/ captcha
A5: PostDeparture | B5: N | C5: Params_4 | D5: Post Departure Plan | E5: w/ captcha
A6: Preview | B6: N | C6: Params_5 | D6: Preview Plan | E6: w/ captcha
A7: Travelkore | B7: Y | C7: Params_6 | D7: Travel Med Go
A8: ANZ | B8: N | C8: Params_7 | D8: Travel Protection Plan
A9: CW | B9: Y | C9: Params_8 | D9: Travel Protection Plan
A10: WM | B10: N | C10: Params_9 | D10: Travel Protection Plan

Sheet Owner_AZ
A1: blnExecute | B1: Step_Number | C1: Step_Name | D1: Status | E1: Error_Check | F1: breakpoint | G1: Test_Case | H1: Page | I1: FindBy | J1: FindBy_Value | K1: Index | L1: Method | M1: Value | N1: Output_Property | O1: Ignore_not_existing_object | P1: isDisabled | Q1: Timeout | R1: Expected_Value | S1: Output_Value | T1: Exact_Match | U1: Contains | V1: ITERATION_NO | W1: Notes | X1: Start_Time | Y1: End_Time | Z1: Duration
A2: Open Owner Advantage URL
A3: =IF(OR(Global!B25="N"),"N","bln677971") -> N | B3: =COUNTA($B$1:B2) -> 1 | C3: Open Browser | G3: Owner Advantage | L3: Wait | M3: 1 | O3: Y | R3: DT_URL
A4: =IF(OR(Global!B25="N"),"N","bln677971") -> N | B4: =COUNTA($B$1:B3) -> 2 | C4: Headless | G4: Owner Advantage | H4: DT_BrowserType | L4: Open | M4: ="URL:="&R3&";;HEADLESS:=TRUE" -> URL:=DT_URL;;HEADLESS:=TRUE | Q4: 60
A5: =IF(OR(Global!B25="Y"),"N","bln677971") -> bln677971 | B5: =COUNTA($B$1:B4) -> 3 | C5: Open Browser | G5: Owner Advantage | H5: DT_BrowserType | L5: Open | M5: DT_URL | Q5: 60
A6: N | B6: =COUNTA($B$1:B5) -> 4 | C6: Wait | G6: Owner Advantage | L6: Wait | M6: 5
A7: N | B7: =COUNTA($B$1:B6) -> 5 | C7: Zscaler Sign in Email | G7: Owner Advantage | I7: xpath | J7: //input[@id='okta-signin-username'] | K7: 0 | L7: Set | M7: DT_ZScalerUser | O7: Y | Q7: 5
A8: N | B8: =COUNTA($B$1:B7) -> 6 | C8: Zscaler Password | G8: Owner Advantage | I8: xpath | J8: //input[@id='okta-signin-password'] | K8: 0 | L8: Set | M8: DT_ZScalerPassword | O8: Y
A9: N | B9: =COUNTA($B$1:B8) -> 7 | C9: Click Sign in | G9: Owner Advantage | I9: xpath | J9: //input[@id='okta-signin-submit'] | K9: 0 | L9: Click | O9: Y
A10: N | B10: =COUNTA($B$1:B9) -> 8 | C10: Wait | G10: Owner Advantage | L10: Wait | M10: 5
A11: Quote - Home Page
A12: bln677971 | B12: =COUNTA($B$1:B11) -> 9 | C12: Switch to Frame | G12: Owner Advantage | L12: SWITCHTOFRAME | M12: aemFormFrame | W12: tripType
A13: bln677971 | B13: =COUNTA($B$1:B12) -> 10 | C13: Check Exist | G13: Owner Advantage | I13: xpath | J13: //button[text()='Accept All Cookies'] | L13: Exist | O13: Y
A14: bln677971 | B14: =COUNTA($B$1:B13) -> 11 | C14: Output Cookie | G14: Owner Advantage | I14: xpath | J14: //button[text()='Accept All Cookies'] | L14: Output | N14: innertext | O14: Y | R14: Accept All Cookies
A15: bln677971 | B15: =COUNTA($B$1:B14) -> 12 | C15: Cookies | G15: Owner Advantage | I15: xpath | J15: //button[@id='onetrust-accept-btn-handler'] | L15: js_click | O15: Y
A16: bln677971 | B16: =COUNTA($B$1:B15) -> 13 | C16: Select Trip Type | G16: Owner Advantage | I16: xpath | J16: ="//label[contains(.,'"&W12&"')]" -> //label[contains(.,'tripType')] | K16: 0 | L16: js_click
A17: bln677971 | B17: =COUNTA($B$1:B16) -> 14 | C17: Click Destination | G17: Owner Advantage | I17: xpath | J17: //input[@id='cmp-Input' and @placeholder='Select a country or region'] | K17: 0 | L17: Click
A18: bln677971 | B18: =COUNTA($B$1:B17) -> 15 | C18: Wait | G18: Owner Advantage | L18: Wait | M18: 2
A19: bln677971 | B19: =COUNTA($B$1:B18) -> 16 | C19: Write Destination | G19: Owner Advantage | I19: xpath | J19: //input[@id='cmp-Input' and @placeholder='Select a country or region'] | K19: 0 | L19: Write | M19: Destination
A20: bln677971 | B20: =COUNTA($B$1:B19) -> 17 | C20: Wait | G20: Owner Advantage | L20: Wait | M20: 2
A21: bln677971 | B21: =COUNTA($B$1:B20) -> 18 | C21: Click Destination | G21: Owner Advantage | I21: xpath | J21: ="//a[contains(.,'"&M19&"')]" -> //a[contains(.,'Destination')] | K21: 0 | L21: js_click
A22: bln677971 | B22: =COUNTA($B$1:B21) -> 19 | C22: Departure Date | G22: Owner Advantage | I22: xpath | J22: //input[@name='tripDepartureDate'] | K22: 0 | L22: Set | M22: DepDate
A23: bln677971 | B23: =COUNTA($B$1:B22) -> 20 | C23: Return Date | G23: Owner Advantage | I23: xpath | J23: //input[@name='tripReturnDate'] | K23: 0 | L23: Set | M23: RetDate
A24: bln677971 | B24: =COUNTA($B$1:B23) -> 21 | C24: Deposit Date | G24: Owner Advantage | I24: xpath | J24: //input[@name='tripDepositDate'] | K24: 0 | L24: Set | M24: DepoDate
A25: bln677971 | B25: =COUNTA($B$1:B24) -> 22 | C25: Click State | G25: Owner Advantage | I25: xpath | J25: //input[@id='cmp-Input' and @placeholder='Select your state'] | K25: 0 | L25: Click
A26: bln677971 | B26: =COUNTA($B$1:B25) -> 23 | C26: Wait | G26: Owner Advantage | L26: Wait | M26: 2
A27: bln677971 | B27: =COUNTA($B$1:B26) -> 24 | C27: Write State | G27: Owner Advantage | I27: xpath | J27: //input[@id='cmp-Input' and @placeholder='Select your state'] | K27: 0 | L27: Write | M27: Residence
A28: bln677971 | B28: =COUNTA($B$1:B27) -> 25 | C28: Wait | G28: Owner Advantage | L28: Wait | M28: 2
A29: bln677971 | B29: =COUNTA($B$1:B28) -> 26 | C29: Click Destination | G29: Owner Advantage | I29: xpath | J29: ="//a[contains(.,'"&M27&"')]" -> //a[contains(.,'Residence')] | K29: 0 | L29: js_click
A30: =IF($W$12="Comprehensive Coverage","Y","N") -> N | B30: =COUNTA($B$1:B29) -> 27 | C30: Enter Age | G30: Owner Advantage | I30: xpath | J30: (//input[@name='insuredAge'])[1] | K30: 0 | L30: Set | M30: Age
A31: =A30 -> N | B31: =COUNTA($B$1:B30) -> 28 | C31: Enter Trip Cost | G31: Owner Advantage | I31: xpath | J31: (//input[@name='display_tripCost'])[1] | K31: 0 | L31: Set | M31: Cost
A32: N | B32: =COUNTA($B$1:B31) -> 29 | C32: Click Add | G32: Owner Advantage | I32: xpath | J32: //button[@id='add-container-button__1'] | K32: 0 | L32: js_click
A33: N | B33: =COUNTA($B$1:B32) -> 30 | C33: Enter Age1 | G33: Owner Advantage | I33: xpath | J33: (//input[@name='insuredAge'])[2] | K33: 0 | L33: Set | M33: Age1
A34: N | B34: =COUNTA($B$1:B33) -> 31 | C34: Enter Trip Cost1 | G34: Owner Advantage | I34: xpath | J34: (//input[@name='display_tripCost'])[2] | K34: 0 | L34: Set | M34: Cost1
A35: N | B35: =COUNTA($B$1:B34) -> 32 | C35: Click Add | G35: Owner Advantage | I35: xpath | J35: //button[@id='add-container-button__2'] | K35: 0 | L35: js_click
A36: N | B36: =COUNTA($B$1:B35) -> 33 | C36: Enter Age2 | G36: Owner Advantage | I36: xpath | J36: (//input[@name='insuredAge'])[3] | K36: 0 | L36: Set | M36: Age2
A37: N | B37: =COUNTA($B$1:B36) -> 34 | C37: Enter Trip Cost2 | G37: Owner Advantage | I37: xpath | J37: (//input[@name='display_tripCost'])[3] | K37: 0 | L37: Set | M37: Cost2
A38: N | B38: =COUNTA($B$1:B37) -> 35 | C38: Click Add | G38: Owner Advantage | I38: xpath | J38: //button[@id='add-container-button__3'] | K38: 0 | L38: js_click
A39: N | B39: =COUNTA($B$1:B38) -> 36 | C39: Enter Age3 | G39: Owner Advantage | I39: xpath | J39: (//input[@name='insuredAge'])[4] | K39: 0 | L39: Set | M39: Age3
A40: N | B40: =COUNTA($B$1:B39) -> 37 | C40: Enter Trip Cost3 | G40: Owner Advantage | I40: xpath | J40: (//input[@name='display_tripCost'])[4] | K40: 0 | L40: Set | M40: Cost3
...

Sheet Params_1
A1: Scenario | B1: blnExecute | C1: bln_TG | D1: blnQuit | E1: bln677971 | F1: DT_BrowserType | G1: Notes | H1: DT_URL | I1: DateToday | J1: PolicyNumber_OUT | K1: tripType | L1: Plan | M1: Destination | N1: Restricted | O1: Destination1 | P1: Destination2 | Q1: Destination3 | R1: Destination4 | S1: Destination5 | T1: Destination6 | U1: Destination7 | V1: Destination8 | W1: Destination9 | X1: Destination10 | Y1: Destination11 | Z1: Destination12 | AA1: Destination13 | AB1: Destination14 | AC1: Destination15 | AD1: Destination16 | AE1: Destination17 | AF1: Destination18 | AG1: Destination19 | AH1: Destination20 | AI1: Destination21 | AJ1: Destination22 | AK1: Destination23 | AL1: Destination24 | AM1: Destination25 | AN1: Destination26 | AO1: Destination27 | AP1: Destination28 | AQ1: Destination29 | AR1: Destination30 | AS1: Destination31 | AT1: Destination32 | AU1: Destination33 | AV1: DepDate | AW1: DepDate1 | AX1: DepDateValid | AY1: RetDate | AZ1: RetDate1 | BA1: RetDateValid | BB1: DepoDate | BC1: DepoYearInvalid | BD1: DepoYearValid | BE1: DepoMonthInvalid | BF1: DepoMonthValid | BG1: DepoDayInvalid | BH1: DepoDayValid | BI1: Residence | BJ1: Residence1 | BK1: Residence2 | BL1: Residence3 | BM1: Residence4 | BN1: Residence5 | BO1: Residence6 | BP1: Residence7 | BQ1: Residence8 | BR1: Residence9 | BS1: Residence10 | BT1: Residence11 | BU1: Residence12 | BV1: Residence13 | BW1: Residence14 | BX1: Residence15 | BY1: Residence16 | BZ1: Residence17 | CA1: Residence18 | CB1: Residence19 | CC1: Residence20 | CD1: Residence21 | CE1: Residence22 | CF1: Residence23 | CG1: Residence24 | CH1: Residence25 | CI1: Residence26 | CJ1: Residence27 | CK1: Residence28 | CL1: Residence29 | CM1: Residence30 | CN1: Residence31 | CO1: Residence32 | CP1: Residence33 | CQ1: Residence34 | CR1: Residence35 | CS1: Residence36 | CT1: Residence37 | CU1: Residence38 | CV1: Residence39 | CW1: Residence40 | CX1: Residence41 | CY1: Residence42 | CZ1: Residence43 | DA1: Residence44 | DB1: Residence45 | DC1: Residence46 | DD1: Residence47 | DE1: Residence48 | DF1: Residence49 | DG1: Residence50 | DH1: Residence51 | DI1: Residence52 | DJ1: Residence53 | DK1: Age | DL1: Cost | DM1: CostAllowed | DN1: Age1 | DO1: Cost1 | DP1: Trav_FirstName1 | DQ1: Trav_LastName1 | DR1: Trav_BirthDate1 | DS1: Age2 | DT1: Cost2 | DU1: Trav_FirstName2 | DV1: Trav_LastName2 | DW1: Trav_BirthDate2 | DX1: Age3 | DY1: Cost3 | DZ1: Trav_FirstName3 | EA1: Trav_LastName3 | EB1: Trav_BirthDate3 | EC1: Age4 | ED1: Cost4 | EE1: Trav_FirstName4 | EF1: Trav_LastName4 | EG1: Trav_BirthDate4 | EH1: Age5 | EI1: Cost5 | EJ1: Trav_FirstName5 | EK1: Trav_LastName5 | EL1: Trav_BirthDate5 | EM1: Age6 | EN1: Cost6 | EO1: Trav_FirstName6 | EP1: Trav_LastName6 | EQ1: Trav_BirthDate6 | ER1: Age7 | ES1: Cost7 | ET1: Trav_FirstName7 | EU1: Trav_LastName7 | EV1: Trav_BirthDate7 | EW1: Age8 | EX1: Cost8 | EY1: Trav_FirstName8 | EZ1: Trav_LastName8 | FA1: Trav_BirthDate8 | FB1: Age9 | FC1: Cost9 | FD1: Trav_FirstName9 | FE1: Trav_LastName9 | FF1: Trav_BirthDate9 | FG1: PickUpDate | FH1: DropOffDate | FI1: PickUpDate1 | FJ1: DropOffDate1 | FK1: PickUpDate2 | FL1: DropOffDate2 | FM1: PickUpDate3 | FN1: DropOffDate3 | FO1: PickUpDate4 | FP1: DropOffDate4 | FQ1: FirstName | FR1: LastName | FS1: BirthDate | FT1: BirthDateInvalid | FU1: BirthDate1 | FV1: Address | FW1: City | FX1: Zip | FY1: ZipX | FZ1: City1 | GA1: Zip1 | GB1: Phone | GC1: Phone1 | GD1: Email | GE1: Email1 | GF1: OwnerPhone | GG1: CardName | GH1: CardNumber | GI1: CardNumber1 | GJ1: ExpiryMonth | GK1: ExpiryYear | GL1: Cost_OUT | GM1: Cost_RES | GN1: Destination_OUT | GO1: Destination_RES | GP1: Plan | GQ1: Plan_OUT | GR1: Plan_RES | GS1: Plan1 | GT1: Plan1_OUT | GU1: Plan_RES | GV1: Plan2 | GW1: Plan2_OUT | GX1: Plan_RES | GY1: ErrorMessage | GZ1: ErrorMessage_OUT | HA1: ErrorMessage_RES | HB1: ErrorMessage1 | HC1: ErrorMessage1_OUT | HD1: ErrorMessage_RES | HE1: ErrorMessage2 | HF1: ErrorMessage2_OUT | HG1: ErrorMessage_RES | HH1: ErrorMessage3 | HI1: ErrorMessage3_OUT | HJ1: ErrorMessage_RES | HK1: Tooltip | HL1: Tooltip_OUT | HM1: Tooltip_RES | HN1: Tooltip1 | HO1: Tooltip1_OUT | HP1: Tooltip1_RES | HQ1: Tooltip2 | HR1: Tooltip2_OUT | HS1: Tooltip2_RES | HT1: FAQ1 | HU1: FAQ1_OUT | HV1: FAQ1_RES | HW1: FAQ2 | HX1: FAQ2_OUT | HY1: FAQ2_RES | HZ1: FAQ3 | IA1: FAQ3_OUT | IB1: FAQ3_RES | IC1: FAQ4 | ID1: FAQ4_OUT | IE1: FAQ4_RES | IF1: FAQ5 | IG1: FAQ5_OUT | IH1: FAQ5_RES | II1: OwnerAdvantagePlan_OUT | IJ1: RentalCarDamagePlan_OUT | IK1: OwnerAdvantagePlan_VERIFY | IL1: RentalCarDamage_VERIFY
A2: bln677971 | B2: Y | C2: Y | D2: Y | E2: Y | F2: Chrome | G2: TC_677971 | H2: {=_xlfn.IFS(Global!B2="QA","https://owneradvantage.qa.insurancebytravelex.com/",Global!B2="UAT","https://owneradvantage.uat.insurancebytravelex.com/",Global!B2="PROD","https://owneradvantage.insurancebytravelex.com/")} -> https://owneradvantage.uat.insurancebytravelex.com/ | I2: =TODAY() -> 46266 | K2: Comprehensive Coverage | L2: Advantage Plan | M2: Singapore | O2: Australia | AV2: =TEXT(I2+1,"mm/dd/yyyy") -> 09/02/2026 | AW2: =TEXT(I2+7,"mm/dd/yyyy") -> 09/08/2026 | AX2: =TEXT(I2+7,"mm/dd/yyyy") -> 09/08/2026 | AY2: =TEXT(AV2+89,"mm/dd/yyyy") -> 11/30/2026 | AZ2: =TEXT(AW2+14,"mm/dd/yyyy") -> 09/22/2026 | BA2: =TEXT(AV2+14,"mm/dd/yyyy") -> 09/16/2026 | BB2: =TEXT(I2-1,"mm/dd/yyyy") -> 08/31/2026 | BI2: California | BJ2: Nebraska | BK2: New York | DK2: 110 | DL2: 1000 | DM2: 100 | DN2: 18 | DO2: 1500 | DP2: ="QAFIRSTNAME"&CHAR(RANDBETWEEN(65,90))&CHAR(RANDBETWEEN(65,90)) -> QAFIRSTNAMEKV | DQ2: ="QALASTNAME"&CHAR(RANDBETWEEN(65,90))&CHAR(RANDBETWEEN(65,90)) -> QALASTNAMESD | DR2: =TEXT(DATE(YEAR(TODAY())-DS2,MONTH(TODAY()),DAY(TODAY())),"MM/DD/YYYY") -> 09/01/2000 | DS2: 26 | DT2: 1500 | DU2: ="QAFIRSTNAME"&CHAR(RANDBETWEEN(65,90))&CHAR(RANDBETWEEN(65,90)) -> QAFIRSTNAMEJE | DV2: ="QALASTNAME"&CHAR(RANDBETWEEN(65,90))&CHAR(RANDBETWEEN(65,90)) -> QALASTNAMEFT | DW2: 01/01/2000 | FG2: =TEXT(AX2,"mm/dd/yyyy") -> 09/08/2026 | FH2: =TEXT(AX2+1,"mm/dd/yyyy") -> 09/09/2026 | FI2: =TEXT(FH2+1,"mm/dd/yyyy") -> 09/10/2026 | FJ2: =TEXT(FI2+1,"mm/dd/yyyy") -> 09/11/2026 | FK2: =TEXT(FJ2+1,"mm/dd/yyyy") -> 09/12/2026 | FL2: =TEXT(FK2+1,"mm/dd/yyyy") -> 09/13/2026 | FM2: =TEXT(FL2+7,"mm/dd/yyyy") -> 09/20/2026 | FN2: =TEXT(FM2+1,"mm/dd/yyyy") -> 09/21/2026 | FO2: =TEXT(FN2+1,"mm/dd/yyyy") -> 09/22/2026 | FP2: =TEXT(FO2+1,"mm/dd/yyyy") -> 09/23/2026 | FQ2: ="QAFIRSTNAME"&CHAR(RANDBETWEEN(65,90))&CHAR(RANDBETWEEN(65,90)) -> QAFIRSTNAMEQB | FR2: ="QALASTNAME"&CHAR(RANDBETWEEN(65,90))&CHAR(RANDBETWEEN(65,90)) -> QALASTNAMEDA | FS2: =TEXT(DATE(YEAR(TODAY())-DK2,MONTH(TODAY()),DAY(TODAY())),"MM/DD/YYYY") -> 09/01/1916 | FU2: =TEXT(DATE(YEAR(TODAY())-DN2,MONTH(TODAY()),DAY(TODAY())),"MM/DD/YYYY") -> 09/01/2008 | FV2: QA213 COR246 | FW2: Los Angeles | FX2: 90001 | FY2: 12345 | FZ2: Omaha | GA2: 68102 | GB2: 1234567897 | GC2: 2222222222 | GD2: qa@travelexinsurance.com | GE2: qa@travelguard.com | GF2: qwertyuiopasdfgh | GG2: QA Test | GH2: 4111111111111111 | GJ2: 12 | GK2: 2030

Sheet Owner_CRVD
A1: blnExecute | B1: Step_Number | C1: Step_Name | D1: Status | E1: Error_Check | F1: breakpoint | G1: Test_Case | H1: Page | I1: FindBy | J1: FindBy_Value | K1: Index | L1: Method | M1: Value | N1: Output_Property | O1: Ignore_not_existing_object | P1: isDisabled | Q1: Timeout | R1: Expected_Value | S1: Output_Value | T1: Exact_Match | U1: Contains | V1: ITERATION_NO | W1: Notes | X1: Start_Time | Y1: End_Time | Z1: Duration
A2: Open Owner Advantage URL
A3: =IF(OR(Global!B25="N"),"N","bln680505") -> N | B3: =COUNTA($B$1:B2) -> 1 | C3: Open Browser | G3: Owner Advantage | L3: Wait | M3: 1 | O3: Y | R3: DT_URL
A4: =IF(OR(Global!B25="N"),"N","bln680505") -> N | B4: =COUNTA($B$1:B3) -> 2 | C4: Headless | G4: Owner Advantage | H4: DT_BrowserType | L4: Open | M4: ="URL:="&R3&";;HEADLESS:=TRUE" -> URL:=DT_URL;;HEADLESS:=TRUE | Q4: 60
A5: =IF(OR(Global!B25="Y"),"N","bln680505") -> bln680505 | B5: =COUNTA($B$1:B4) -> 3 | C5: Open Browser | G5: Owner Advantage | H5: DT_BrowserType | L5: Open | M5: DT_URL | Q5: 60
A6: N | B6: =COUNTA($B$1:B5) -> 4 | C6: Wait | G6: Owner Advantage | L6: Wait | M6: 5
A7: N | B7: =COUNTA($B$1:B6) -> 5 | C7: Zscaler Sign in Email | G7: Owner Advantage | I7: xpath | J7: //input[@id='okta-signin-username'] | K7: 0 | L7: Set | M7: DT_ZScalerUser | O7: Y | Q7: 5
A8: N | B8: =COUNTA($B$1:B7) -> 6 | C8: Zscaler Password | G8: Owner Advantage | I8: xpath | J8: //input[@id='okta-signin-password'] | K8: 0 | L8: Set | M8: DT_ZScalerPassword | O8: Y
A9: N | B9: =COUNTA($B$1:B8) -> 7 | C9: Click Sign in | G9: Owner Advantage | I9: xpath | J9: //input[@id='okta-signin-submit'] | K9: 0 | L9: Click | O9: Y
A10: N | B10: =COUNTA($B$1:B9) -> 8 | C10: Wait | G10: Owner Advantage | L10: Wait | M10: 5
A11: Quote - Home Page
A12: bln680505 | B12: =COUNTA($B$1:B11) -> 9 | C12: Switch to Frame | G12: Owner Advantage | L12: SWITCHTOFRAME | M12: aemFormFrame | W12: tripType
A13: bln680505 | B13: =COUNTA($B$1:B12) -> 10 | C13: Check Exist | G13: Owner Advantage | I13: xpath | J13: //button[text()='Accept All Cookies'] | L13: Exist | O13: Y
A14: bln680505 | B14: =COUNTA($B$1:B13) -> 11 | C14: Output Cookie | G14: Owner Advantage | I14: xpath | J14: //button[text()='Accept All Cookies'] | L14: Output | N14: innertext | O14: Y | R14: Accept All Cookies
A15: bln680505 | B15: =COUNTA($B$1:B14) -> 12 | C15: Cookies | G15: Owner Advantage | I15: xpath | J15: //button[@id='onetrust-accept-btn-handler'] | L15: js_click | O15: Y
A16: bln680505 | B16: =COUNTA($B$1:B15) -> 13 | C16: Select Trip Type | G16: Owner Advantage | I16: xpath | J16: ="//label[contains(.,'"&W12&"')]" -> //label[contains(.,'tripType')] | K16: 0 | L16: js_click
A17: bln680505 | B17: =COUNTA($B$1:B16) -> 14 | C17: Click Destination | G17: Owner Advantage | I17: xpath | J17: //input[@id='cmp-Input' and @placeholder='Select a country or region'] | K17: 0 | L17: Click
A18: bln680505 | B18: =COUNTA($B$1:B17) -> 15 | C18: Wait | G18: Owner Advantage | L18: Wait | M18: 2
A19: bln680505 | B19: =COUNTA($B$1:B18) -> 16 | C19: Write Destination | G19: Owner Advantage | I19: xpath | J19: //input[@id='cmp-Input' and @placeholder='Select a country or region'] | K19: 0 | L19: Write | M19: Destination
A20: bln680505 | B20: =COUNTA($B$1:B19) -> 17 | C20: Wait | G20: Owner Advantage | L20: Wait | M20: 2
A21: bln680505 | B21: =COUNTA($B$1:B20) -> 18 | C21: Click Destination | G21: Owner Advantage | I21: xpath | J21: ="//a[contains(.,'"&M19&"')]" -> //a[contains(.,'Destination')] | K21: 0 | L21: js_click
A22: bln680505 | B22: =COUNTA($B$1:B21) -> 19 | C22: Departure Date | G22: Owner Advantage | I22: xpath | J22: //input[@name='tripDepartureDate'] | K22: 0 | L22: Set | M22: DepDate
A23: bln680505 | B23: =COUNTA($B$1:B22) -> 20 | C23: Return Date | G23: Owner Advantage | I23: xpath | J23: //input[@name='tripReturnDate'] | K23: 0 | L23: Set | M23: RetDate
A24: bln680505 | B24: =COUNTA($B$1:B23) -> 21 | C24: Deposit Date | G24: Owner Advantage | I24: xpath | J24: //input[@name='tripDepositDate'] | K24: 0 | L24: Set | M24: DepoDate
A25: bln680505 | B25: =COUNTA($B$1:B24) -> 22 | C25: Click State | G25: Owner Advantage | I25: xpath | J25: //input[@id='cmp-Input' and @placeholder='Select your state'] | K25: 0 | L25: Click
A26: bln680505 | B26: =COUNTA($B$1:B25) -> 23 | C26: Wait | G26: Owner Advantage | L26: Wait | M26: 2
A27: bln680505 | B27: =COUNTA($B$1:B26) -> 24 | C27: Write State | G27: Owner Advantage | I27: xpath | J27: //input[@id='cmp-Input' and @placeholder='Select your state'] | K27: 0 | L27: Write | M27: Residence
A28: bln680505 | B28: =COUNTA($B$1:B27) -> 25 | C28: Wait | G28: Owner Advantage | L28: Wait | M28: 2
A29: bln680505 | B29: =COUNTA($B$1:B28) -> 26 | C29: Click Destination | G29: Owner Advantage | I29: xpath | J29: ="//a[contains(.,'"&M27&"')]" -> //a[contains(.,'Residence')] | K29: 0 | L29: js_click
A30: bln680505 | B30: =COUNTA($B$1:B29) -> 27 | C30: Enter Age | G30: Owner Advantage | I30: xpath | J30: (//input[@name='insuredAge'])[1] | K30: 0 | L30: Set | M30: Age
A31: bln680505 | B31: =COUNTA($B$1:B30) -> 28 | C31: Enter Trip Cost | G31: Owner Advantage | I31: xpath | J31: (//input[@name='display_tripCost'])[1] | K31: 0 | L31: Set | M31: Cost
A32: N | B32: =COUNTA($B$1:B31) -> 29 | C32: Click Add | G32: Owner Advantage | I32: xpath | J32: //button[@id='add-container-button__1'] | K32: 0 | L32: js_click
A33: N | B33: =COUNTA($B$1:B32) -> 30 | C33: Enter Age1 | G33: Owner Advantage | I33: xpath | J33: (//input[@name='insuredAge'])[2] | K33: 0 | L33: Set | M33: Age1
A34: N | B34: =COUNTA($B$1:B33) -> 31 | C34: Enter Trip Cost1 | G34: Owner Advantage | I34: xpath | J34: (//input[@name='display_tripCost'])[2] | K34: 0 | L34: Set | M34: Cost1
A35: N | B35: =COUNTA($B$1:B34) -> 32 | C35: Click Add | G35: Owner Advantage | I35: xpath | J35: //button[@id='add-container-button__2'] | K35: 0 | L35: js_click
A36: N | B36: =COUNTA($B$1:B35) -> 33 | C36: Enter Age2 | G36: Owner Advantage | I36: xpath | J36: (//input[@name='insuredAge'])[3] | K36: 0 | L36: Set | M36: Age2
A37: N | B37: =COUNTA($B$1:B36) -> 34 | C37: Enter Trip Cost2 | G37: Owner Advantage | I37: xpath | J37: (//input[@name='display_tripCost'])[3] | K37: 0 | L37: Set | M37: Cost2
A38: N | B38: =COUNTA($B$1:B37) -> 35 | C38: Click Add | G38: Owner Advantage | I38: xpath | J38: //button[@id='add-container-button__3'] | K38: 0 | L38: js_click
A39: N | B39: =COUNTA($B$1:B38) -> 36 | C39: Enter Age3 | G39: Owner Advantage | I39: xpath | J39: (//input[@name='insuredAge'])[4] | K39: 0 | L39: Set | M39: Age3
A40: N | B40: =COUNTA($B$1:B39) -> 37 | C40: Enter Trip Cost3 | G40: Owner Advantage | I40: xpath | J40: (//input[@name='display_tripCost'])[4] | K40: 0 | L40: Set | M40: Cost3
...

Sheet Params_2
A1: Scenario | B1: blnExecute | C1: bln_TG | D1: blnQuit | E1: bln680505 | F1: DT_BrowserType | G1: Notes | H1: DT_URL | I1: DateToday | J1: PolicyNumber_OUT | K1: tripType | L1: Plan | M1: Destination | N1: Restricted | O1: Destination1 | P1: Destination2 | Q1: Destination3 | R1: Destination4 | S1: Destination5 | T1: Destination6 | U1: Destination7 | V1: Destination8 | W1: Destination9 | X1: Destination10 | Y1: Destination11 | Z1: Destination12 | AA1: Destination13 | AB1: Destination14 | AC1: Destination15 | AD1: Destination16 | AE1: Destination17 | AF1: Destination18 | AG1: Destination19 | AH1: Destination20 | AI1: Destination21 | AJ1: Destination22 | AK1: Destination23 | AL1: Destination24 | AM1: Destination25 | AN1: Destination26 | AO1: Destination27 | AP1: Destination28 | AQ1: Destination29 | AR1: Destination30 | AS1: Destination31 | AT1: Destination32 | AU1: Destination33 | AV1: DepDate | AW1: DepDate1 | AX1: DepDateValid | AY1: RetDate | AZ1: RetDate1 | BA1: RetDateValid | BB1: DepoDate | BC1: DepoYearInvalid | BD1: DepoYearValid | BE1: DepoMonthInvalid | BF1: DepoMonthValid | BG1: DepoDayInvalid | BH1: DepoDayValid | BI1: Residence | BJ1: Residence1 | BK1: Residence2 | BL1: Residence3 | BM1: Residence4 | BN1: Residence5 | BO1: Residence6 | BP1: Residence7 | BQ1: Residence8 | BR1: Residence9 | BS1: Residence10 | BT1: Residence11 | BU1: Residence12 | BV1: Residence13 | BW1: Residence14 | BX1: Residence15 | BY1: Residence16 | BZ1: Residence17 | CA1: Residence18 | CB1: Residence19 | CC1: Residence20 | CD1: Residence21 | CE1: Residence22 | CF1: Residence23 | CG1: Residence24 | CH1: Residence25 | CI1: Residence26 | CJ1: Residence27 | CK1: Residence28 | CL1: Residence29 | CM1: Residence30 | CN1: Residence31 | CO1: Residence32 | CP1: Residence33 | CQ1: Residence34 | CR1: Residence35 | CS1: Residence36 | CT1: Residence37 | CU1: Residence38 | CV1: Residence39 | CW1: Residence40 | CX1: Residence41 | CY1: Residence42 | CZ1: Residence43 | DA1: Residence44 | DB1: Residence45 | DC1: Residence46 | DD1: Residence47 | DE1: Residence48 | DF1: Residence49 | DG1: Residence50 | DH1: Residence51 | DI1: Residence52 | DJ1: Residence53 | DK1: Age | DL1: Cost | DM1: CostAllowed | DN1: Age1 | DO1: Cost1 | DP1: Trav_FirstName1 | DQ1: Trav_LastName1 | DR1: Trav_BirthDate1 | DS1: Age2 | DT1: Cost2 | DU1: Trav_FirstName2 | DV1: Trav_LastName2 | DW1: Trav_BirthDate2 | DX1: Age3 | DY1: Cost3 | DZ1: Trav_FirstName3 | EA1: Trav_LastName3 | EB1: Trav_BirthDate3 | EC1: Age4 | ED1: Cost4 | EE1: Trav_FirstName4 | EF1: Trav_LastName4 | EG1: Trav_BirthDate4 | EH1: Age5 | EI1: Cost5 | EJ1: Trav_FirstName5 | EK1: Trav_LastName5 | EL1: Trav_BirthDate5 | EM1: Age6 | EN1: Cost6 | EO1: Trav_FirstName6 | EP1: Trav_LastName6 | EQ1: Trav_BirthDate6 | ER1: Age7 | ES1: Cost7 | ET1: Trav_FirstName7 | EU1: Trav_LastName7 | EV1: Trav_BirthDate7 | EW1: Age8 | EX1: Cost8 | EY1: Trav_FirstName8 | EZ1: Trav_LastName8 | FA1: Trav_BirthDate8 | FB1: Age9 | FC1: Cost9 | FD1: Trav_FirstName9 | FE1: Trav_LastName9 | FF1: Trav_BirthDate9 | FG1: PickUpDate | FH1: DropOffDate | FI1: PickUpDate1 | FJ1: DropOffDate1 | FK1: PickUpDate2 | FL1: DropOffDate2 | FM1: PickUpDate3 | FN1: DropOffDate3 | FO1: PickUpDate4 | FP1: DropOffDate4 | FQ1: FirstName | FR1: LastName | FS1: BirthDate | FT1: BirthDateInvalid | FU1: BirthDate1 | FV1: Address | FW1: City | FX1: Zip | FY1: ZipX | FZ1: City1 | GA1: Zip1 | GB1: Phone | GC1: Phone1 | GD1: Email | GE1: Email1 | GF1: OwnerPhone | GG1: CardName | GH1: CardNumber | GI1: CardNumber1 | GJ1: ExpiryMonth | GK1: ExpiryYear | GL1: Cost_OUT | GM1: Cost_RES | GN1: Destination_OUT | GO1: Destination_RES | GP1: Plan | GQ1: Plan_OUT | GR1: Plan_RES | GS1: Plan1 | GT1: Plan1_OUT | GU1: Plan_RES | GV1: Plan2 | GW1: Plan2_OUT | GX1: Plan_RES | GY1: ErrorMessage | GZ1: ErrorMessage_OUT | HA1: ErrorMessage_RES | HB1: ErrorMessage1 | HC1: ErrorMessage1_OUT | HD1: ErrorMessage_RES | HE1: ErrorMessage2 | HF1: ErrorMessage2_OUT | HG1: ErrorMessage_RES | HH1: ErrorMessage3 | HI1: ErrorMessage3_OUT | HJ1: ErrorMessage_RES | HK1: Tooltip | HL1: Tooltip_OUT | HM1: Tooltip_RES | HN1: Tooltip1 | HO1: Tooltip1_OUT | HP1: Tooltip1_RES | HQ1: Tooltip2 | HR1: Tooltip2_OUT | HS1: Tooltip2_RES | HT1: FAQ1 | HU1: FAQ1_OUT | HV1: FAQ1_RES | HW1: FAQ2 | HX1: FAQ2_OUT | HY1: FAQ2_RES | HZ1: FAQ3 | IA1: FAQ3_OUT | IB1: FAQ3_RES | IC1: FAQ4 | ID1: FAQ4_OUT | IE1: FAQ4_RES | IF1: FAQ5 | IG1: FAQ5_OUT | IH1: FAQ5_RES | II1: OwnerAdvantagePlan_OUT | IJ1: RentalCarDamagePlan_OUT | IK1: OwnerAdvantagePlan_VERIFY | IL1: RentalCarDamage_VERIFY
A2: bln680505 | B2: Y | C2: Y | D2: Y | E2: Y | F2: Chrome | G2: TC_680505 | H2: {=_xlfn.IFS(Global!B2="QA","https://owneradvantage.qa.insurancebytravelex.com/",Global!B2="UAT","https://owneradvantage.uat.insurancebytravelex.com/",Global!B2="PROD","https://owneradvantage.insurancebytravelex.com/")} -> https://owneradvantage.uat.insurancebytravelex.com/ | I2: =TODAY() -> 46266 | K2: Comprehensive Coverage | L2: Rental Car Damage Plan | M2: Singapore | O2: Australia | AV2: =TEXT(I2+1,"mm/dd/yyyy") -> 09/02/2026 | AW2: =TEXT(I2+7,"mm/dd/yyyy") -> 09/08/2026 | AX2: =TEXT(I2+7,"mm/dd/yyyy") -> 09/08/2026 | AY2: =TEXT(AV2+89,"mm/dd/yyyy") -> 11/30/2026 | AZ2: =TEXT(AW2+15,"mm/dd/yyyy") -> 09/23/2026 | BA2: =TEXT(AV2+21,"mm/dd/yyyy") -> 09/23/2026 | BB2: =TEXT(I2-1,"mm/dd/yyyy") -> 08/31/2026 | BI2: California | BJ2: Nebraska | BK2: New York | DK2: 110 | DL2: 1000 | DM2: 100 | DN2: 18 | DO2: 1500 | DP2: ="QAFIRSTNAME"&CHAR(RANDBETWEEN(65,90))&CHAR(RANDBETWEEN(65,90)) -> QAFIRSTNAMEFS | DQ2: ="QALASTNAME"&CHAR(RANDBETWEEN(65,90))&CHAR(RANDBETWEEN(65,90)) -> QALASTNAMEHD | DR2: =TEXT(DATE(YEAR(TODAY())-DS2,MONTH(TODAY()),DAY(TODAY())),"MM/DD/YYYY") -> 09/01/2026 | FG2: =TEXT(AV2,"mm/dd/yyyy") -> 09/02/2026 | FH2: =TEXT(AV2+1,"mm/dd/yyyy") -> 09/03/2026 | FI2: =TEXT(FH2+1,"mm/dd/yyyy") -> 09/04/2026 | FJ2: =TEXT(FI2+1,"mm/dd/yyyy") -> 09/05/2026 | FK2: =TEXT(FJ2+1,"mm/dd/yyyy") -> 09/06/2026 | FL2: =TEXT(FK2+1,"mm/dd/yyyy") -> 09/07/2026 | FM2: =TEXT(FL2+7,"mm/dd/yyyy") -> 09/14/2026 | FN2: =TEXT(FM2+1,"mm/dd/yyyy") -> 09/15/2026 | FO2: =TEXT(FN2+1,"mm/dd/yyyy") -> 09/16/2026 | FP2: =TEXT(FO2+1,"mm/dd/yyyy") -> 09/17/2026 | FQ2: ="QAFIRSTNAME"&CHAR(RANDBETWEEN(65,90))&CHAR(RANDBETWEEN(65,90)) -> QAFIRSTNAMEBL | FR2: ="QALASTNAME"&CHAR(RANDBETWEEN(65,90))&CHAR(RANDBETWEEN(65,90)) -> QALASTNAMEJA | FS2: =TEXT(DATE(YEAR(TODAY())-DK2,MONTH(TODAY()),DAY(TODAY())),"MM/DD/YYYY") -> 09/01/1916 | FU2: =TEXT(DATE(YEAR(TODAY())-DN2,MONTH(TODAY()),DAY(TODAY())),"MM/DD/YYYY") -> 09/01/2008 | FV2: QA213 COR246 | FW2: Los Angeles | FX2: 90001 | FY2: 12345 | FZ2: Omaha | GA2: 68102 | GB2: 1234567897 | GC2: 2222222222 | GD2: qa@travelexinsurance.com | GE2: qa@travelguard.com | GF2: qwertyuiopasdfgh | GG2: QA Test | GH2: 4111111111111111 | GJ2: 12 | GK2: 2030 | GM2: =IF(DL2=GL2,"PASSED","FAILED") -> FAILED

Sheet Owner_RVD
A1: blnExecute | B1: Step_Number | C1: Step_Name | D1: Status | E1: Error_Check | F1: breakpoint | G1: Test_Case | H1: Page | I1: FindBy | J1: FindBy_Value | K1: Index | L1: Method | M1: Value | N1: Output_Property | O1: Ignore_not_existing_object | P1: isDisabled | Q1: Timeout | R1: Expected_Value | S1: Output_Value | T1: Exact_Match | U1: Contains | V1: ITERATION_NO | W1: Notes | X1: Start_Time | Y1: End_Time | Z1: Duration
A2: Open Owner Advantage URL
A3: =IF(OR(Global!B25="N"),"N","bln678042") -> N | B3: =COUNTA($B$1:B2) -> 1 | C3: Open Browser | G3: Owner Advantage | L3: Wait | M3: 1 | O3: Y | R3: DT_URL
A4: =IF(OR(Global!B25="N"),"N","bln678042") -> N | B4: =COUNTA($B$1:B3) -> 2 | C4: Headless | G4: Owner Advantage | H4: DT_BrowserType | L4: Open | M4: ="URL:="&R3&";;HEADLESS:=TRUE" -> URL:=DT_URL;;HEADLESS:=TRUE | Q4: 60
A5: =IF(OR(Global!B25="Y"),"N","bln678042") -> bln678042 | B5: =COUNTA($B$1:B4) -> 3 | C5: Open Browser | G5: Owner Advantage | H5: DT_BrowserType | L5: Open | M5: DT_URL | Q5: 60
A6: N | B6: =COUNTA($B$1:B5) -> 4 | C6: Wait | G6: Owner Advantage | L6: Wait | M6: 5
A7: N | B7: =COUNTA($B$1:B6) -> 5 | C7: Zscaler Sign in Email | G7: Owner Advantage | I7: xpath | J7: //input[@id='okta-signin-username'] | K7: 0 | L7: Set | M7: DT_ZScalerUser | O7: Y | Q7: 5
A8: N | B8: =COUNTA($B$1:B7) -> 6 | C8: Zscaler Password | G8: Owner Advantage | I8: xpath | J8: //input[@id='okta-signin-password'] | K8: 0 | L8: Set | M8: DT_ZScalerPassword | O8: Y
A9: N | B9: =COUNTA($B$1:B8) -> 7 | C9: Click Sign in | G9: Owner Advantage | I9: xpath | J9: //input[@id='okta-signin-submit'] | K9: 0 | L9: Click | O9: Y
A10: N | B10: =COUNTA($B$1:B9) -> 8 | C10: Wait | G10: Owner Advantage | L10: Wait | M10: 5
A11: Quote - Home Page
A12: bln678042 | B12: =COUNTA($B$1:B11) -> 9 | C12: Switch to Frame | G12: Owner Advantage | L12: SWITCHTOFRAME | M12: aemFormFrame | W12: tripType
A13: bln678042 | B13: =COUNTA($B$1:B12) -> 10 | C13: Check Exist | G13: Owner Advantage | I13: xpath | J13: //button[text()='Accept All Cookies'] | L13: Exist | O13: Y
A14: =IF($D$13="PASSED","bln678042","N") -> N | B14: =COUNTA($B$1:B13) -> 11 | C14: Output Cookie | G14: Owner Advantage | I14: xpath | J14: //button[text()='Accept All Cookies'] | K14: 0 | L14: Output | N14: innertext | O14: Y | R14: Accept All Cookies
A15: =A14 -> N | B15: =COUNTA($B$1:B14) -> 12 | C15: Cookies | G15: Owner Advantage | I15: xpath | J15: //button[@id='onetrust-accept-btn-handler'] | K15: 0 | L15: js_click | O15: Y
A16: bln678042 | B16: =COUNTA($B$1:B15) -> 13 | C16: Select Trip Type | G16: Owner Advantage | I16: xpath | J16: ="//label[contains(.,'"&W12&"')]" -> //label[contains(.,'tripType')] | K16: 0 | L16: js_click
A17: bln678042 | B17: =COUNTA($B$1:B16) -> 14 | C17: Click Destination | G17: Owner Advantage | I17: xpath | J17: //input[@id='cmp-Input' and @placeholder='Select a country or region'] | K17: 0 | L17: Click
A18: bln678042 | B18: =COUNTA($B$1:B17) -> 15 | C18: Wait | G18: Owner Advantage | L18: Wait | M18: 2
A19: bln678042 | B19: =COUNTA($B$1:B18) -> 16 | C19: Write Destination | G19: Owner Advantage | I19: xpath | J19: //input[@id='cmp-Input' and @placeholder='Select a country or region'] | K19: 0 | L19: Write | M19: Destination
A20: bln678042 | B20: =COUNTA($B$1:B19) -> 17 | C20: Wait | G20: Owner Advantage | L20: Wait | M20: 2
A21: bln678042 | B21: =COUNTA($B$1:B20) -> 18 | C21: Click Destination | G21: Owner Advantage | I21: xpath | J21: ="//a[contains(.,'"&M19&"')]" -> //a[contains(.,'Destination')] | K21: 0 | L21: js_click
A22: bln678042 | B22: =COUNTA($B$1:B21) -> 19 | C22: Departure Date | G22: Owner Advantage | I22: xpath | J22: //input[@name='tripDepartureDate'] | K22: 0 | L22: Set | M22: DepDate
A23: bln678042 | B23: =COUNTA($B$1:B22) -> 20 | C23: Return Date | G23: Owner Advantage | I23: xpath | J23: //input[@name='tripReturnDate'] | K23: 0 | L23: Set | M23: RetDate
A24: bln678042 | B24: =COUNTA($B$1:B23) -> 21 | C24: Deposit Date | G24: Owner Advantage | I24: xpath | J24: //input[@name='tripDepositDate'] | K24: 0 | L24: Set | M24: DepoDate
A25: bln678042 | B25: =COUNTA($B$1:B24) -> 22 | C25: Click State | G25: Owner Advantage | I25: xpath | J25: //input[@id='cmp-Input' and @placeholder='Select your state'] | K25: 0 | L25: Click
A26: bln678042 | B26: =COUNTA($B$1:B25) -> 23 | C26: Wait | G26: Owner Advantage | L26: Wait | M26: 2
A27: bln678042 | B27: =COUNTA($B$1:B26) -> 24 | C27: Write State | G27: Owner Advantage | I27: xpath | J27: //input[@id='cmp-Input' and @placeholder='Select your state'] | K27: 0 | L27: Write | M27: Residence
A28: bln678042 | B28: =COUNTA($B$1:B27) -> 25 | C28: Wait | G28: Owner Advantage | L28: Wait | M28: 2
A29: bln678042 | B29: =COUNTA($B$1:B28) -> 26 | C29: Click Destination | G29: Owner Advantage | I29: xpath | J29: ="//a[contains(.,'"&M27&"')]" -> //a[contains(.,'Residence')] | K29: 0 | L29: js_click
A30: bln678042 | B30: =COUNTA($B$1:B29) -> 27 | C30: Click Submit button | G30: Owner Advantage | I30: xpath | J30: //button[@type='SUBMIT'] | K30: 0 | L30: js_click
A31: bln678042 | B31: =COUNTA($B$1:B30) -> 28 | C31: Wait | G31: Owner Advantage | L31: Wait | M31: 10
A32: Plan Option and Upgrades
A33: bln678042 | B33: =COUNTA($B$1:B32) -> 29 | C33: Check Exist | G33: Owner Advantage | I33: xpath | J33: //button[text()='Accept All Cookies'] | L33: Exist | O33: Y
A34: =IF($D$33="PASSED","bln678042","N") -> N | B34: =COUNTA($B$1:B33) -> 30 | C34: Output Cookie | G34: Owner Advantage | I34: xpath | J34: //button[text()='Accept All Cookies'] | K34: 0 | L34: Output | N34: innertext | O34: Y | R34: Accept All Cookies
A35: =A34 -> N | B35: =COUNTA($B$1:B34) -> 31 | C35: Cookies | G35: Owner Advantage | I35: xpath | J35: //button[@id='onetrust-accept-btn-handler'] | K35: 0 | L35: js_click | O35: Y
A36: bln678042 | B36: =COUNTA($B$1:B35) -> 32 | C36: Click the My Trip dropdown next to the total premium | G36: Owner Advantage | I36: xpath | J36: (//button[@type='button'])[2] | K36: 0 | L36: js_click
A37: =IF(Global!B2="QA","Y","N") -> N | B37: =COUNTA($B$1:B36) -> 33 | C37: Verify the displayed Destination | G37: Owner Advantage | I37: xpath | J37: //div[@class='cmp-text']//span[contains(@class,'destinationCountry_multi_display')] | K37: 0 | L37: Output | N37: innertext | R37: =TEXT(M19,"0") -> Destination | T37: Y
A38: =A37 -> N | B38: =COUNTA($B$1:B37) -> 34 | C38: Verify the displayed Trip Dates match the selected Departure Date | G38: Owner Advantage | I38: xpath | J38: (//div[@class='cmp-text']//span[contains(@class,'tripDepartureDate')])[1] | K38: 0 | L38: Output | N38: innertext | R38: =TEXT(M22,"mm/dd/yyyy") -> DepDate | T38: Y
A39: =A38 -> N | B39: =COUNTA($B$1:B38) -> 35 | C39: Verify the displayed Trip Dates match the selected Return Dates | G39: Owner Advantage | I39: xpath | J39: (//div[@class='cmp-text']//span[contains(@class,'tripReturnDate')])[1] | K39: 0 | L39: Output | N39: innertext | R39: =TEXT(M23,"mm/dd/yyyy") -> RetDate | T39: Y
A40: =A39 -> N | B40: =COUNTA($B$1:B39) -> 36 | C40: Select Rental Car Damage Plan | G40: Owner Advantage | I40: xpath | J40: //button[@name='selectPlan' and @value='MRCDZ-0925'] | K40: 0 | L40: js_click
...

Sheet Params_3
A1: Scenario | B1: blnExecute | C1: bln_TG | D1: blnQuit | E1: bln678042 | F1: DT_BrowserType | G1: Notes | H1: DT_URL | I1: DateToday | J1: PolicyNumber_OUT | K1: tripType | L1: Plan | M1: Destination | N1: Restricted | O1: Destination1 | P1: Destination2 | Q1: Destination3 | R1: Destination4 | S1: Destination5 | T1: Destination6 | U1: Destination7 | V1: Destination8 | W1: Destination9 | X1: Destination10 | Y1: Destination11 | Z1: Destination12 | AA1: Destination13 | AB1: Destination14 | AC1: Destination15 | AD1: Destination16 | AE1: Destination17 | AF1: Destination18 | AG1: Destination19 | AH1: Destination20 | AI1: Destination21 | AJ1: Destination22 | AK1: Destination23 | AL1: Destination24 | AM1: Destination25 | AN1: Destination26 | AO1: Destination27 | AP1: Destination28 | AQ1: Destination29 | AR1: Destination30 | AS1: Destination31 | AT1: Destination32 | AU1: Destination33 | AV1: DepDate | AW1: DepDate1 | AX1: DepDateValid | AY1: RetDate | AZ1: RetDate1 | BA1: RetDateValid | BB1: DepoDate | BC1: DepoYearInvalid | BD1: DepoYearValid | BE1: DepoMonthInvalid | BF1: DepoMonthValid | BG1: DepoDayInvalid | BH1: DepoDayValid | BI1: Residence | BJ1: Residence1 | BK1: Residence2 | BL1: Residence3 | BM1: Residence4 | BN1: Residence5 | BO1: Residence6 | BP1: Residence7 | BQ1: Residence8 | BR1: Residence9 | BS1: Residence10 | BT1: Residence11 | BU1: Residence12 | BV1: Residence13 | BW1: Residence14 | BX1: Residence15 | BY1: Residence16 | BZ1: Residence17 | CA1: Residence18 | CB1: Residence19 | CC1: Residence20 | CD1: Residence21 | CE1: Residence22 | CF1: Residence23 | CG1: Residence24 | CH1: Residence25 | CI1: Residence26 | CJ1: Residence27 | CK1: Residence28 | CL1: Residence29 | CM1: Residence30 | CN1: Residence31 | CO1: Residence32 | CP1: Residence33 | CQ1: Residence34 | CR1: Residence35 | CS1: Residence36 | CT1: Residence37 | CU1: Residence38 | CV1: Residence39 | CW1: Residence40 | CX1: Residence41 | CY1: Residence42 | CZ1: Residence43 | DA1: Residence44 | DB1: Residence45 | DC1: Residence46 | DD1: Residence47 | DE1: Residence48 | DF1: Residence49 | DG1: Residence50 | DH1: Residence51 | DI1: Residence52 | DJ1: Residence53 | DK1: Age | DL1: Cost | DM1: CostAllowed | DN1: Age1 | DO1: Cost1 | DP1: Trav_FirstName1 | DQ1: Trav_LastName1 | DR1: Trav_BirthDate1 | DS1: Age2 | DT1: Cost2 | DU1: Trav_FirstName2 | DV1: Trav_LastName2 | DW1: Trav_BirthDate2 | DX1: Age3 | DY1: Cost3 | DZ1: Trav_FirstName3 | EA1: Trav_LastName3 | EB1: Trav_BirthDate3 | EC1: Age4 | ED1: Cost4 | EE1: Trav_FirstName4 | EF1: Trav_LastName4 | EG1: Trav_BirthDate4 | EH1: Age5 | EI1: Cost5 | EJ1: Trav_FirstName5 | EK1: Trav_LastName5 | EL1: Trav_BirthDate5 | EM1: Age6 | EN1: Cost6 | EO1: Trav_FirstName6 | EP1: Trav_LastName6 | EQ1: Trav_BirthDate6 | ER1: Age7 | ES1: Cost7 | ET1: Trav_FirstName7 | EU1: Trav_LastName7 | EV1: Trav_BirthDate7 | EW1: Age8 | EX1: Cost8 | EY1: Trav_FirstName8 | EZ1: Trav_LastName8 | FA1: Trav_BirthDate8 | FB1: Age9 | FC1: Cost9 | FD1: Trav_FirstName9 | FE1: Trav_LastName9 | FF1: Trav_BirthDate9 | FG1: PickUpDate | FH1: DropOffDate | FI1: PickUpDate1 | FJ1: DropOffDate1 | FK1: PickUpDate2 | FL1: DropOffDate2 | FM1: PickUpDate3 | FN1: DropOffDate3 | FO1: PickUpDate4 | FP1: DropOffDate4 | FQ1: FirstName | FR1: LastName | FS1: BirthDate | FT1: BirthDateInvalid | FU1: BirthDate1 | FV1: Address | FW1: City | FX1: Zip | FY1: ZipX | FZ1: City1 | GA1: Zip1 | GB1: Phone | GC1: Phone1 | GD1: Email | GE1: Email1 | GF1: OwnerPhone | GG1: CardName | GH1: CardNumber | GI1: CardNumber1 | GJ1: ExpiryMonth | GK1: ExpiryYear | GL1: Cost_OUT | GM1: Cost_RES | GN1: Destination_OUT | GO1: Destination_RES | GP1: Plan | GQ1: Plan_OUT | GR1: Plan_RES | GS1: Plan1 | GT1: Plan1_OUT | GU1: Plan_RES | GV1: Plan2 | GW1: Plan2_OUT | GX1: Plan_RES | GY1: ErrorMessage | GZ1: ErrorMessage_OUT | HA1: ErrorMessage_RES | HB1: ErrorMessage1 | HC1: ErrorMessage1_OUT | HD1: ErrorMessage_RES | HE1: ErrorMessage2 | HF1: ErrorMessage2_OUT | HG1: ErrorMessage_RES | HH1: ErrorMessage3 | HI1: ErrorMessage3_OUT | HJ1: ErrorMessage_RES | HK1: Tooltip | HL1: Tooltip_OUT | HM1: Tooltip_RES | HN1: Tooltip1 | HO1: Tooltip1_OUT | HP1: Tooltip1_RES | HQ1: Tooltip2 | HR1: Tooltip2_OUT | HS1: Tooltip2_RES | HT1: FAQ1 | HU1: FAQ1_OUT | HV1: FAQ1_RES | HW1: FAQ2 | HX1: FAQ2_OUT | HY1: FAQ2_RES | HZ1: FAQ3 | IA1: FAQ3_OUT | IB1: FAQ3_RES | IC1: FAQ4 | ID1: FAQ4_OUT | IE1: FAQ4_RES | IF1: FAQ5 | IG1: FAQ5_OUT | IH1: FAQ5_RES | II1: OwnerAdvantagePlan_OUT | IJ1: RentalCarDamagePlan_OUT | IK1: OwnerAdvantagePlan_VERIFY | IL1: RentalCarDamage_VERIFY
A2: bln678042 | B2: Y | C2: Y | D2: Y | E2: Y | F2: Chrome | G2: TC_678042 | H2: {=_xlfn.IFS(Global!B2="QA","https://owneradvantage.qa.insurancebytravelex.com/",Global!B2="UAT","https://owneradvantage.uat.insurancebytravelex.com/",Global!B2="PROD","https://owneradvantage.insurancebytravelex.com/")} -> https://owneradvantage.uat.insurancebytravelex.com/ | I2: =TODAY() -> 46266 | K2: Rental Car Coverage | L2: Rental Car Damage Plan | M2: Singapore | O2: Australia | AV2: =TEXT(I2+1,"mm/dd/yyyy") -> 09/02/2026 | AW2: =TEXT(I2+7,"mm/dd/yyyy") -> 09/08/2026 | AX2: =TEXT(I2+7,"mm/dd/yyyy") -> 09/08/2026 | AY2: =TEXT(AV2+89,"mm/dd/yyyy") -> 11/30/2026 | AZ2: =TEXT(AW2+14,"mm/dd/yyyy") -> 09/22/2026 | BA2: =TEXT(AV2+14,"mm/dd/yyyy") -> 09/16/2026 | BB2: =TEXT(I2-1,"mm/dd/yyyy") -> 08/31/2026 | BI2: California | BJ2: Nebraska | BK2: New York | DK2: 110 | DL2: 1000 | DM2: 100 | DN2: 18 | DO2: 1500 | DP2: ="QAFIRSTNAME"&CHAR(RANDBETWEEN(65,90))&CHAR(RANDBETWEEN(65,90)) -> QAFIRSTNAMETY | DQ2: ="QALASTNAME"&CHAR(RANDBETWEEN(65,90))&CHAR(RANDBETWEEN(65,90)) -> QALASTNAMEUX | DR2: =TEXT(DATE(YEAR(TODAY())-DS2,MONTH(TODAY()),DAY(TODAY())),"MM/DD/YYYY") -> 09/01/2026 | FG2: =TEXT(AX2,"mm/dd/yyyy") -> 09/08/2026 | FH2: =TEXT(AX2+1,"mm/dd/yyyy") -> 09/09/2026 | FI2: =TEXT(FH2+1,"mm/dd/yyyy") -> 09/10/2026 | FJ2: =TEXT(FI2+1,"mm/dd/yyyy") -> 09/11/2026 | FK2: =TEXT(FJ2+1,"mm/dd/yyyy") -> 09/12/2026 | FL2: =TEXT(FK2+1,"mm/dd/yyyy") -> 09/13/2026 | FM2: =TEXT(FL2+7,"mm/dd/yyyy") -> 09/20/2026 | FN2: =TEXT(FM2+1,"mm/dd/yyyy") -> 09/21/2026 | FO2: =TEXT(FN2+1,"mm/dd/yyyy") -> 09/22/2026 | FP2: =TEXT(FO2+1,"mm/dd/yyyy") -> 09/23/2026 | FQ2: ="QAFIRSTNAME"&CHAR(RANDBETWEEN(65,90))&CHAR(RANDBETWEEN(65,90)) -> QAFIRSTNAMEKA | FR2: ="QALASTNAME"&CHAR(RANDBETWEEN(65,90))&CHAR(RANDBETWEEN(65,90)) -> QALASTNAMEBG | FS2: =TEXT(DATE(YEAR(TODAY())-DK2,MONTH(TODAY()),DAY(TODAY())),"MM/DD/YYYY") -> 09/01/1916 | FU2: =TEXT(DATE(YEAR(TODAY())-DN2,MONTH(TODAY()),DAY(TODAY())),"MM/DD/YYYY") -> 09/01/2008 | FV2: QA213 COR246 | FW2: San Diego | FX2: 92101 | FY2: 12345 | FZ2: Omaha | GA2: 68102 | GB2: 1234567897 | GC2: 2222222222 | GD2: qa@travelexinsurance.com | GE2: qa@travelguard.com | GF2: qwertyuiopasdfgh | GG2: QA Test | GH2: 4111111111111111 | GJ2: 12 | GK2: 2030

Sheet PostDeparture
A1: blnExecute | B1: Step_Number | C1: Step_Name | D1: Status | E1: Error_Check | F1: breakpoint | G1: Test_Case | H1: Page | I1: FindBy | J1: FindBy_Value | K1: Index | L1: Method | M1: Value | N1: Output_Property | O1: Ignore_not_existing_object | P1: isDisabled | Q1: Timeout | R1: Expected_Value | S1: Output_Value | T1: Exact_Match | U1: Contains | V1: ITERATION_NO | W1: Notes | X1: Start_Time | Y1: End_Time | Z1: Duration
A2: Open Post Departure URL
A3: =IF(OR(Global!B25="N"),"N","bln680922") -> N | B3: =COUNTA($B$1:B2) -> 1 | C3: Open Browser | G3: Post Departure | L3: Wait | M3: 1 | O3: Y | R3: DT_URL
A4: =IF(OR(Global!B25="N"),"N","bln680922") -> N | B4: =COUNTA($B$1:B3) -> 2 | C4: Headless | G4: Post Departure | H4: DT_BrowserType | L4: Open | M4: ="URL:="&R3&";;HEADLESS:=TRUE" -> URL:=DT_URL;;HEADLESS:=TRUE | Q4: 60
A5: =IF(OR(Global!B25="Y"),"N","bln680922") -> bln680922 | B5: =COUNTA($B$1:B4) -> 3 | C5: Open Browser | G5: Post Departure | H5: DT_BrowserType | L5: Open | M5: DT_URL | Q5: 60
A6: N | B6: =COUNTA($B$1:B5) -> 4 | C6: Wait | G6: Post Departure | L6: Wait | M6: 5
A7: N | B7: =COUNTA($B$1:B6) -> 5 | C7: Zscaler Sign in Email | G7: Post Departure | I7: xpath | J7: //input[@id='okta-signin-username'] | K7: 0 | L7: Set | M7: DT_ZScalerUser | O7: Y | Q7: 5
A8: N | B8: =COUNTA($B$1:B7) -> 6 | C8: Zscaler Password | G8: Post Departure | I8: xpath | J8: //input[@id='okta-signin-password'] | K8: 0 | L8: Set | M8: DT_ZScalerPassword | O8: Y
A9: N | B9: =COUNTA($B$1:B8) -> 7 | C9: Click Sign in | G9: Post Departure | I9: xpath | J9: //input[@id='okta-signin-submit'] | K9: 0 | L9: Click | O9: Y
A10: N | B10: =COUNTA($B$1:B9) -> 8 | C10: Wait | G10: Post Departure | L10: Wait | M10: 5
A11: Quote - Home Page
A12: bln680922 | B12: =COUNTA($B$1:B11) -> 9 | C12: Switch to Frame | G12: Post Departure | L12: SWITCHTOFRAME | M12: aemFormFrame
A13: bln680922 | B13: =COUNTA($B$1:B12) -> 10 | C13: Check Exist | G13: Post Departure | I13: xpath | J13: //button[text()='Accept All Cookies'] | L13: Exist | O13: Y
A14: =IF($D$13="PASSED","bln680922","N") -> N | B14: =COUNTA($B$1:B13) -> 11 | C14: Output Cookie | G14: Post Departure | I14: xpath | J14: //button[text()='Accept All Cookies'] | L14: Output | N14: innertext | O14: Y | R14: Accept All Cookies
A15: =A14 -> N | B15: =COUNTA($B$1:B14) -> 12 | C15: Cookies | G15: Post Departure | I15: xpath | J15: //button[@id='onetrust-accept-btn-handler'] | L15: js_click | O15: Y
A16: bln680922 | B16: =COUNTA($B$1:B15) -> 13 | C16: Click Destination | G16: Post Departure | I16: xpath | J16: //input[@id='cmp-Input' and @placeholder='Select a country or region'] | K16: 0 | L16: Click
A17: bln680922 | B17: =COUNTA($B$1:B16) -> 14 | C17: Wait | G17: Post Departure | L17: Wait | M17: 2
A18: bln680922 | B18: =COUNTA($B$1:B17) -> 15 | C18: Write Destination | G18: Post Departure | I18: xpath | J18: //input[@id='cmp-Input' and @placeholder='Select a country or region'] | K18: 0 | L18: Write | M18: Destination
A19: bln680922 | B19: =COUNTA($B$1:B18) -> 16 | C19: Wait | G19: Post Departure | L19: Wait | M19: 2
A20: bln680922 | B20: =COUNTA($B$1:B19) -> 17 | C20: Click Destination | G20: Post Departure | I20: xpath | J20: ="//a[contains(.,'"&M18&"')]" -> //a[contains(.,'Destination')] | K20: 0 | L20: js_click
A21: bln680922 | B21: =COUNTA($B$1:B20) -> 18 | C21: Departure Date | G21: Post Departure | I21: xpath | J21: //input[@name='tripDepartureDate'] | K21: 0 | L21: Set | M21: DepDate
A22: bln680922 | B22: =COUNTA($B$1:B21) -> 19 | C22: Return Date | G22: Post Departure | I22: xpath | J22: //input[@name='tripReturnDate'] | K22: 0 | L22: Set | M22: RetDate
A23: bln680922 | B23: =COUNTA($B$1:B22) -> 20 | C23: Click State | G23: Post Departure | I23: xpath | J23: //input[@id='cmp-Input' and @placeholder='Select your state'] | K23: 0 | L23: Click
A24: bln680922 | B24: =COUNTA($B$1:B23) -> 21 | C24: Wait | G24: Post Departure | L24: Wait | M24: 2
A25: bln680922 | B25: =COUNTA($B$1:B24) -> 22 | C25: Write State | G25: Post Departure | I25: xpath | J25: //input[@id='cmp-Input' and @placeholder='Select your state'] | K25: 0 | L25: Write | M25: Residence
A26: bln680922 | B26: =COUNTA($B$1:B25) -> 23 | C26: Wait | G26: Post Departure | L26: Wait | M26: 2
A27: bln680922 | B27: =COUNTA($B$1:B26) -> 24 | C27: Click Destination | G27: Post Departure | I27: xpath | J27: ="//a[contains(.,'"&M25&"')]" -> //a[contains(.,'Residence')] | K27: 0 | L27: js_click
A28: bln680922 | B28: =COUNTA($B$1:B27) -> 25 | C28: Enter Age | G28: Post Departure | I28: xpath | J28: (//input[@name='insuredAge'])[1] | K28: 0 | L28: Set | M28: Age
A29: bln680922 | B29: =COUNTA($B$1:B28) -> 26 | C29: Click Submit button | G29: Post Departure | I29: xpath | J29: //button[@type='SUBMIT'] | K29: 0 | L29: js_click
A30: bln680922 | B30: =COUNTA($B$1:B29) -> 27 | C30: Wait | G30: Post Departure | L30: Wait | M30: 10
A31: Plan Option and Upgrades
A32: bln680922 | B32: =COUNTA($B$1:B31) -> 28 | C32: Check Exist | G32: Post Departure | I32: xpath | J32: //button[text()='Accept All Cookies'] | L32: Exist | O32: Y
A33: =IF($D$32="PASSED","bln680922","N") -> N | B33: =COUNTA($B$1:B32) -> 29 | C33: Output Cookie | G33: Post Departure | I33: xpath | J33: //button[text()='Accept All Cookies'] | L33: Output | N33: innertext | O33: Y | R33: Accept All Cookies
A34: =A33 -> N | B34: =COUNTA($B$1:B33) -> 30 | C34: Cookies | G34: Post Departure | I34: xpath | J34: //button[@id='onetrust-accept-btn-handler'] | L34: js_click | O34: Y
A35: bln680922 | B35: =COUNTA($B$1:B34) -> 31 | C35: Select Post Departure Plan | G35: Post Departure | I35: xpath | J35: //button[@name='selectPlan' and @value='MPDZ-0925'] | K35: 0 | L35: js_click
A36: bln680922 | B36: =COUNTA($B$1:B35) -> 32 | C36: Wait | G36: Post Departure | L36: Wait | M36: 2
A37: bln680922 | B37: =COUNTA($B$1:B36) -> 33 | C37: Select No Rental Car Damage | G37: Post Departure | I37: xpath | J37: //input[@name='RVD_addOn' and @value='No'] | K37: 0 | L37: js_click
A38: bln680922 | B38: =COUNTA($B$1:B37) -> 34 | C38: Click Submit button | G38: Post Departure | I38: xpath | J38: //button[@type='SUBMIT'] | K38: 0 | L38: js_click
A39: bln680922 | B39: =COUNTA($B$1:B38) -> 35 | C39: Wait | G39: Post Departure | L39: Wait | M39: 10
A40: Travelers Information
...

Sheet Params_4
A1: Scenario | B1: blnExecute | C1: bln_TG | D1: blnQuit | E1: bln680922 | F1: DT_BrowserType | G1: Notes | H1: DT_URL | I1: DateToday | J1: PolicyNumber_OUT | K1: tripType | L1: Plan | M1: Destination | N1: Restricted | O1: Destination1 | P1: Destination2 | Q1: Destination3 | R1: Destination4 | S1: Destination5 | T1: Destination6 | U1: Destination7 | V1: Destination8 | W1: Destination9 | X1: Destination10 | Y1: Destination11 | Z1: Destination12 | AA1: Destination13 | AB1: Destination14 | AC1: Destination15 | AD1: Destination16 | AE1: Destination17 | AF1: Destination18 | AG1: Destination19 | AH1: Destination20 | AI1: Destination21 | AJ1: Destination22 | AK1: Destination23 | AL1: Destination24 | AM1: Destination25 | AN1: Destination26 | AO1: Destination27 | AP1: Destination28 | AQ1: Destination29 | AR1: Destination30 | AS1: Destination31 | AT1: Destination32 | AU1: Destination33 | AV1: DepDate | AW1: DepDate1 | AX1: DepDateValid | AY1: RetDate | AZ1: RetDate1 | BA1: RetDateValid | BB1: DepoDate | BC1: DepoYearInvalid | BD1: DepoYearValid | BE1: DepoMonthInvalid | BF1: DepoMonthValid | BG1: DepoDayInvalid | BH1: DepoDayValid | BI1: Residence | BJ1: Residence1 | BK1: Residence2 | BL1: Residence3 | BM1: Residence4 | BN1: Residence5 | BO1: Residence6 | BP1: Residence7 | BQ1: Residence8 | BR1: Residence9 | BS1: Residence10 | BT1: Residence11 | BU1: Residence12 | BV1: Residence13 | BW1: Residence14 | BX1: Residence15 | BY1: Residence16 | BZ1: Residence17 | CA1: Residence18 | CB1: Residence19 | CC1: Residence20 | CD1: Residence21 | CE1: Residence22 | CF1: Residence23 | CG1: Residence24 | CH1: Residence25 | CI1: Residence26 | CJ1: Residence27 | CK1: Residence28 | CL1: Residence29 | CM1: Residence30 | CN1: Residence31 | CO1: Residence32 | CP1: Residence33 | CQ1: Residence34 | CR1: Residence35 | CS1: Residence36 | CT1: Residence37 | CU1: Residence38 | CV1: Residence39 | CW1: Residence40 | CX1: Residence41 | CY1: Residence42 | CZ1: Residence43 | DA1: Residence44 | DB1: Residence45 | DC1: Residence46 | DD1: Residence47 | DE1: Residence48 | DF1: Residence49 | DG1: Residence50 | DH1: Residence51 | DI1: Residence52 | DJ1: Residence53 | DK1: Age | DL1: Cost | DM1: CostAllowed | DN1: Age1 | DO1: Cost1 | DP1: Trav_FirstName1 | DQ1: Trav_LastName1 | DR1: Trav_BirthDate1 | DS1: Age2 | DT1: Cost2 | DU1: Trav_FirstName2 | DV1: Trav_LastName2 | DW1: Trav_BirthDate2 | DX1: Age3 | DY1: Cost3 | DZ1: Trav_FirstName3 | EA1: Trav_LastName3 | EB1: Trav_BirthDate3 | EC1: Age4 | ED1: Cost4 | EE1: Trav_FirstName4 | EF1: Trav_LastName4 | EG1: Trav_BirthDate4 | EH1: Age5 | EI1: Cost5 | EJ1: Trav_FirstName5 | EK1: Trav_LastName5 | EL1: Trav_BirthDate5 | EM1: Age6 | EN1: Cost6 | EO1: Trav_FirstName6 | EP1: Trav_LastName6 | EQ1: Trav_BirthDate6 | ER1: Age7 | ES1: Cost7 | ET1: Trav_FirstName7 | EU1: Trav_LastName7 | EV1: Trav_BirthDate7 | EW1: Age8 | EX1: Cost8 | EY1: Trav_FirstName8 | EZ1: Trav_LastName8 | FA1: Trav_BirthDate8 | FB1: Age9 | FC1: Cost9 | FD1: Trav_FirstName9 | FE1: Trav_LastName9 | FF1: Trav_BirthDate9 | FG1: PickUpDate | FH1: DropOffDate | FI1: PickUpDate1 | FJ1: DropOffDate1 | FK1: PickUpDate2 | FL1: DropOffDate2 | FM1: PickUpDate3 | FN1: DropOffDate3 | FO1: PickUpDate4 | FP1: DropOffDate4 | FQ1: FirstName | FR1: LastName | FS1: BirthDate | FT1: BirthDateInvalid | FU1: BirthDate1 | FV1: Address | FW1: City | FX1: Zip | FY1: ZipX | FZ1: City1 | GA1: Zip1 | GB1: Phone | GC1: Phone1 | GD1: Email | GE1: Email1 | GF1: OwnerPhone | GG1: CardName | GH1: CardNumber | GI1: CardNumber1 | GJ1: ExpiryMonth | GK1: ExpiryYear | GL1: Cost_OUT | GM1: Cost_RES | GN1: Destination_OUT | GO1: Destination_RES | GP1: Plan | GQ1: Plan_OUT | GR1: Plan_RES | GS1: Plan1 | GT1: Plan1_OUT | GU1: Plan_RES | GV1: Plan2 | GW1: Plan2_OUT | GX1: Plan_RES | GY1: ErrorMessage | GZ1: ErrorMessage_OUT | HA1: ErrorMessage_RES | HB1: ErrorMessage1 | HC1: ErrorMessage1_OUT | HD1: ErrorMessage_RES | HE1: ErrorMessage2 | HF1: ErrorMessage2_OUT | HG1: ErrorMessage_RES | HH1: ErrorMessage3 | HI1: ErrorMessage3_OUT | HJ1: ErrorMessage_RES | HK1: Tooltip | HL1: Tooltip_OUT | HM1: Tooltip_RES | HN1: Tooltip1 | HO1: Tooltip1_OUT | HP1: Tooltip1_RES | HQ1: Tooltip2 | HR1: Tooltip2_OUT | HS1: Tooltip2_RES | HT1: FAQ1 | HU1: FAQ1_OUT | HV1: FAQ1_RES | HW1: FAQ2 | HX1: FAQ2_OUT | HY1: FAQ2_RES | HZ1: FAQ3 | IA1: FAQ3_OUT | IB1: FAQ3_RES | IC1: FAQ4 | ID1: FAQ4_OUT | IE1: FAQ4_RES | IF1: FAQ5 | IG1: FAQ5_OUT | IH1: FAQ5_RES | II1: OwnerAdvantagePlan_OUT | IJ1: RentalCarDamagePlan_OUT | IK1: OwnerAdvantagePlan_VERIFY | IL1: RentalCarDamage_VERIFY
A2: bln680922 | B2: Y | C2: Y | D2: Y | E2: Y | F2: Chrome | G2: TC_680922 | H2: {=_xlfn.IFS(Global!B2="QA","https://departure.qa.insurancebytravelex.com",Global!B2="UAT","https://departure.uat.insurancebytravelex.com",Global!B2="PROD","https://departure.insurancebytravelex.com/")} -> https://departure.uat.insurancebytravelex.com | I2: =TODAY() -> 46266 | L2: Post Departure Plan | M2: Singapore | O2: Australia | AV2: =TEXT(I2+1,"mm/dd/yyyy") -> 09/02/2026 | AW2: =TEXT(I2+7,"mm/dd/yyyy") -> 09/08/2026 | AX2: =TEXT(I2+7,"mm/dd/yyyy") -> 09/08/2026 | AY2: =TEXT(AV2+29,"mm/dd/yyyy") -> 10/01/2026 | AZ2: =TEXT(AW2+14,"mm/dd/yyyy") -> 09/22/2026 | BA2: =TEXT(AV2+14,"mm/dd/yyyy") -> 09/16/2026 | BB2: =TEXT(I2-1,"mm/dd/yyyy") -> 08/31/2026 | BI2: California | BJ2: Nebraska | BK2: New York | DK2: 110 | DL2: 1000 | DM2: 100 | DN2: 18 | DO2: 1500 | DP2: ="QAFIRSTNAME"&CHAR(RANDBETWEEN(65,90))&CHAR(RANDBETWEEN(65,90)) -> QAFIRSTNAMEDY | DQ2: ="QALASTNAME"&CHAR(RANDBETWEEN(65,90))&CHAR(RANDBETWEEN(65,90)) -> QALASTNAMEOH | DR2: =TEXT(DATE(YEAR(TODAY())-DS2,MONTH(TODAY()),DAY(TODAY())),"MM/DD/YYYY") -> 09/01/2000 | DS2: 26 | DT2: 1500 | DU2: ="QAFIRSTNAME"&CHAR(RANDBETWEEN(65,90))&CHAR(RANDBETWEEN(65,90)) -> QAFIRSTNAMEIE | DV2: ="QALASTNAME"&CHAR(RANDBETWEEN(65,90))&CHAR(RANDBETWEEN(65,90)) -> QALASTNAMENJ | DW2: 01/01/2000 | FG2: =TEXT(AX2,"mm/dd/yyyy") -> 09/08/2026 | FH2: =TEXT(AX2+1,"mm/dd/yyyy") -> 09/09/2026 | FI2: =TEXT(FH2+1,"mm/dd/yyyy") -> 09/10/2026 | FJ2: =TEXT(FI2+1,"mm/dd/yyyy") -> 09/11/2026 | FK2: =TEXT(FJ2+1,"mm/dd/yyyy") -> 09/12/2026 | FL2: =TEXT(FK2+1,"mm/dd/yyyy") -> 09/13/2026 | FM2: =TEXT(FL2+7,"mm/dd/yyyy") -> 09/20/2026 | FN2: =TEXT(FM2+1,"mm/dd/yyyy") -> 09/21/2026 | FO2: =TEXT(FN2+1,"mm/dd/yyyy") -> 09/22/2026 | FP2: =TEXT(FO2+1,"mm/dd/yyyy") -> 09/23/2026 | FQ2: ="QAFIRSTNAME"&CHAR(RANDBETWEEN(65,90))&CHAR(RANDBETWEEN(65,90)) -> QAFIRSTNAMERX | FR2: ="QALASTNAME"&CHAR(RANDBETWEEN(65,90))&CHAR(RANDBETWEEN(65,90)) -> QALASTNAMENF | FS2: =TEXT(DATE(YEAR(TODAY())-DK2,MONTH(TODAY()),DAY(TODAY())),"MM/DD/YYYY") -> 09/01/1916 | FU2: =TEXT(DATE(YEAR(TODAY())-DN2,MONTH(TODAY()),DAY(TODAY())),"MM/DD/YYYY") -> 09/01/2008 | FV2: QA213 COR246 | FW2: Los Angeles | FX2: 90001 | FY2: 12345 | FZ2: Omaha | GA2: 68102 | GB2: 1234567897 | GC2: 2222222222 | GD2: qa@travelexinsurance.com | GE2: qa@travelguard.com | GF2: qwertyuiopasdfgh | GG2: QA Test | GH2: 4111111111111111 | GJ2: 12 | GK2: 2030

Sheet Preview
A1: blnExecute | B1: Step_Number | C1: Step_Name | D1: Status | E1: Error_Check | F1: breakpoint | G1: Test_Case | H1: Page | I1: FindBy | J1: FindBy_Value | K1: Index | L1: Method | M1: Value | N1: Output_Property | O1: Ignore_not_existing_object | P1: isDisabled | Q1: Timeout | R1: Expected_Value | S1: Output_Value | T1: Exact_Match | U1: Contains | V1: ITERATION_NO | W1: Notes | X1: Start_Time | Y1: End_Time | Z1: Duration
A2: Open Preview URL
A3: =IF(OR(Global!B25="N"),"N","bln680759") -> N | B3: =COUNTA($B$1:B2) -> 1 | C3: Open Browser | G3: Preview | L3: Wait | M3: 1 | O3: Y | R3: DT_URL
A4: =IF(OR(Global!B25="N"),"N","bln680759") -> N | B4: =COUNTA($B$1:B3) -> 2 | C4: Headless | G4: Preview | H4: DT_BrowserType | L4: Open | M4: ="URL:="&R3&";;HEADLESS:=TRUE" -> URL:=DT_URL;;HEADLESS:=TRUE | Q4: 60
A5: =IF(OR(Global!B25="Y"),"N","bln680759") -> bln680759 | B5: =COUNTA($B$1:B4) -> 3 | C5: Open Browser | G5: Preview | H5: DT_BrowserType | L5: Open | M5: DT_URL | Q5: 60
A6: N | B6: =COUNTA($B$1:B5) -> 4 | C6: Wait | G6: Preview | L6: Wait | M6: 5
A7: N | B7: =COUNTA($B$1:B6) -> 5 | C7: Zscaler Sign in Email | G7: Preview | I7: xpath | J7: //input[@id='okta-signin-username'] | K7: 0 | L7: Set | M7: DT_ZScalerUser | O7: Y | Q7: 5
A8: N | B8: =COUNTA($B$1:B7) -> 6 | C8: Zscaler Password | G8: Preview | I8: xpath | J8: //input[@id='okta-signin-password'] | K8: 0 | L8: Set | M8: DT_ZScalerPassword | O8: Y
A9: N | B9: =COUNTA($B$1:B8) -> 7 | C9: Click Sign in | G9: Preview | I9: xpath | J9: //input[@id='okta-signin-submit'] | K9: 0 | L9: Click | O9: Y
A10: N | B10: =COUNTA($B$1:B9) -> 8 | C10: Wait | G10: Preview | L10: Wait | M10: 5
A11: Quote - Home Page
A12: bln680759 | B12: =COUNTA($B$1:B11) -> 9 | C12: Switch to Frame | G12: Preview | L12: SWITCHTOFRAME | M12: aemFormFrame
A13: bln680759 | B13: =COUNTA($B$1:B12) -> 10 | C13: Check Exist | G13: Preview | I13: xpath | J13: //button[text()='Accept All Cookies'] | L13: Exist | O13: Y
A14: =IF($D$13="PASSED","bln680759","N") -> N | B14: =COUNTA($B$1:B13) -> 11 | C14: Output Cookie | G14: Preview | I14: xpath | J14: //button[text()='Accept All Cookies'] | L14: Output | N14: innertext | O14: Y | R14: Accept All Cookies
A15: =A14 -> N | B15: =COUNTA($B$1:B14) -> 12 | C15: Cookies | G15: Preview | I15: xpath | J15: //button[@id='onetrust-accept-btn-handler'] | L15: js_click | O15: Y
