Workbook
Name Australia_States: [1]Reference!$B$2:$B$9
Name Australia_States: [2]Reference!$B$2:$B$9
Name Canada_Provinces: [1]Reference!$C$2:$C$14
Name Canada_Provinces: [2]Reference!$C$2:$C$14
Name Currency_List: [1]Reference!$A$2:$A$120
Name Currency_List: [2]Reference!$A$2:$A$120
Name US_States: [1]Reference!$D$2:$D$53
Name US_States: [2]Reference!$D$2:$D$53

Sheet Datasheets
A1: SheetsToExecute | B1: blnExecute | C1: ParameterSheet | D1: Comments
A2: Qantas | B2: Y | C2: Qantas_Params
A3: AgentStandAlone | B3: Y | C3: AgentStandAlone_Params
A4: PolicySearch | B4: Y
A5: Qantas_AgentPortal | B5: N | C5: Qantas_AgentPortal_Params
A6: Qantas_PROD | B6: N | C6: Qantas_PROD_Params

Sheet Global
A1: Parameter | B1: Value | C1: Comments | E1: Env | F1: URL
A2: Environment | B2: UAT | E2: QA | F2: https://qantas.qa.travelguard.com | G2: https://api.qa.travelguard.com/policy/v4/ | H2: https://agents.qa.travelguard.com/content/tg-agents/qantas/en/login.html
A3: ResultFileLocation | B3: ="L:\Regression\Test Results\Temp_Results\AEM Regression\Qantas\"&B2&"\"&B9&"_"&TEXT(NOW(),"yyyyy-mmm-dd-hhmm")&"_"&23&"\" -> L:\Regression\Test Results\Temp_Results\AEM Regression\Qantas\UAT\Qantas StandAlone - Staff Daily Regression_2026-May-18-1215_23\ | E3: UAT | F3: https://qantas.uat.travelguard.com | G3: https://api.uat.travelguard.com/policy/v4/ | H3: https://agents.uat.travelguard.com/content/tg-agents/qantas/en/login.html
A4: ResultFilename | B4: =B9&"_"&TEXT(NOW(),"yyyymmdd-hhmmss")&".xlsx" -> Qantas StandAlone - Staff Daily Regression_20260518-121537.xlsx
A5: isHTMLParsing | B5: Y | C5: Default is False. XML parsing will be used for default
A6: removeNamespacesInResponse | B6: N | C6: Default is False
A7: sendOutlookMail | B7: N | C7: Default is True
A8: CreateHtmlReport | B8: Y | C8: Used for reporting. If this parameter is missing or blank, default behavior is True (html report will be generated)
A9: ResultTitle | B9: Qantas StandAlone - Staff Daily Regression | C9: Used for reporting. If this parameter is missing or blank, default value is used "Test Run Result".
A10: Notes | C10: Used for reporting. If this parameter is missing or blank, default value is used "N/A".
A11: TC_Name_Column | B11: TC_Name | C11: Used for reporting. This is required. If this is missing, result summary table of the report will be empty.
A12: TC_ID_Column | B12: TCID
A13: EmailSubject
A14: SendEmailTO
A15: SendEmailCC
A16: EmailRunTimeDatasheet | B16: N
A17: PauseOnFail | B17: N
A18: QuitBreakOnFailure | B18: Y
A19: Application | B19: Qantas | C19: =B3 -> L:\Regression\Test Results\Temp_Results\AEM Regression\Qantas\UAT\Qantas StandAlone - Staff Daily Regression_2026-May-18-1215_23\
A20: isOfficial | B20: N
A21: ManualTestHours | B21: 1
A22: Cycle | B22: 1
A23: WorkItemNumber | B23: N
A24: WorkItemDescription | B24: N

Sheet InputOutput
A1: Function | B1: Parameter | C1: Value
A2: addHeader | B2: Authorization | C2: DT_bearerToken
A3: addHeader | B3: apiKey | C3: DT_apiKey
A4: INPUT_Contract
A5: update_json | B5: searchCriteria.searchParameters.[0].value | C5: policyNumber_IN
A6: update_json | B6: searchCriteria.searchParameters.[1].value | C6: lastName_IN
A7: OUTPUT_Contract
A8: output_json | B8: aigContractId | C8: aigContractId_OUT
A9: output_json | B9: aigContractNumber | C9: aigContractNumber_OUT
A10: output_json | B10: contractNumber | C10: contractNumber_OUT
A11: output_json | B11: messageValues | C11: errors_OUT
A12: output_json | B12: detailResponse.transactionLog.transactionStatus | C12: transactionStatus_OUT
A13: output_json | B13: detailResponse.policyDetail.travelers.[0].customElements.[1].value | C13: MedScen01_OUT
B14: detailResponse.policyDetail.travelers.[0].customElements.[2].value | C14: MedScen02_OUT
B15: detailResponse.policyDetail.travelers.[0].customElements.[4].value | C15: MedScen03_OUT
A16: output_json | B16: detailResponse.policyDetail.accountDetail.agent.email | C16: AgentEmail_OUT
A17: output_json | B17: detailResponse.policyDetail.displayStatus | C17: PolicyStatus_OUT
A18: COMPARE_Contract
A19: compareX | B19: RES_STATUS_CD_EXP | C19: RES_STATUS_CD_OUT
A20: compareX | B20: errors_EXP | C20: errors_OUT
A21: compare | B21: transactionStatus_EXP | C21: transactionStatus_OUT
A22: compare | B22: MedScen01_EXP | C22: MedScen01_OUT
B23: MedScen02_EXP | C23: MedScen02_OUT
B24: MedScen03_EXP | C24: MedScen03_OUT
A25: compare | B25: AgentEmail_EXP | C25: AgentEmail_OUT
A26: compare | B26: PolicyStatus_EXP | C26: PolicyStatus_OUT
A27: DISABLE CHECKPOINT
A28: DisableCheckpoint | B28: Generate Token | C28: errors_OUT;successful_OUT

Sheet Qantas_PROD
A1: blnExecute | B1: Step_Number | C1: Step_Name | D1: Status | E1: Error_Check | F1: breakpoint | G1: Test_Case | H1: Page | I1: FindBy | J1: FindBy_Value | K1: Index | L1: Method | M1: Value | N1: Output_Property | O1: Ignore_not_existing_object | P1: isDisabled | Q1: Timeout | R1: Expected_Value | S1: Output_Value | T1: Exact_Match | U1: Contains | V1: Notes | W1: Start_Time | X1: End_Time | Y1: Duration
A2: Open Site
A3: Y | B3: =COUNTA($C$2:C3) -> 1 | C3: Launch Site | G3: DT_Scenario | H3: chrome | K3: 0 | L3: Open | M3: DT_URL
A4: N | B4: =COUNTA($C$2:C4) -> 2 | C4: Wait | G4: DT_Scenario | L4: Wait | M4: 5
A5: N | B5: =COUNTA($C$2:C5) -> 3 | C5: Zscaler Sign in Email | G5: DT_Scenario | I5: xpath | J5: //input[@id='okta-signin-username'] | K5: 0 | L5: Set | M5: DT_ZScalerUser | O5: Y | Q5: 5
A6: N | B6: =COUNTA($C$2:C6) -> 4 | C6: Zscaler Password | G6: DT_Scenario | I6: xpath | J6: //input[@id='okta-signin-password'] | K6: 0 | L6: Set | M6: DT_ZScalerPassword | O6: Y
A7: N | B7: =COUNTA($C$2:C7) -> 5 | C7: Click Sign in | G7: DT_Scenario | I7: xpath | J7: //input[@id='okta-signin-submit'] | K7: 0 | L7: Click | O7: Y
A8: N | B8: =COUNTA($C$2:C8) -> 6 | C8: Wait | G8: DT_Scenario | L8: Wait | M8: 5
A9: Qantas Purchase Path
A10: N | B10: =COUNTA($C$2:C10) -> 7 | C10: Click Login Icon | G10: DT_Scenario | I10: xpath | J10: //span[contains(.,'Log in')] | K10: 0 | L10: Click
A11: N | B11: =COUNTA($C$2:C11) -> 8 | C11: Wait | G11: DT_Scenario | L11: Wait | M11: 5
A12: N | B12: =COUNTA($C$2:C12) -> 9 | C12: Enter Membership Number | G12: DT_Scenario | I12: xpath | J12: //input[@name='memberId'] | K12: 0 | L12: Set | M12: DT_Login_MemberNo
A13: N | B13: =COUNTA($C$2:C13) -> 10 | C13: Enter Last Name | G13: DT_Scenario | I13: xpath | J13: //input[@name='lastName'] | K13: 0 | L13: Set | M13: DT_Login_Lastname
A14: N | B14: =COUNTA($C$2:C14) -> 11 | C14: Enter PIN | G14: DT_Scenario | I14: xpath | J14: //input[@type='password'] | K14: 0 | L14: Set | M14: DT_Login_PIN
A15: N | B15: =COUNTA($C$2:C15) -> 12 | C15: Click Login | G15: DT_Scenario | I15: xpath | J15: //button[contains(.,'LOG IN')] | K15: 0 | L15: Click
A16: N | B16: =COUNTA($C$2:C16) -> 13 | C16: Wait | G16: DT_Scenario | L16: Wait | M16: 3
A17: N | B17: =COUNTA($C$2:C17) -> 14 | C17: Enter Verification | G17: DT_Scenario | I17: xpath | J17: //input[@name='verifyCode'] | K17: 0 | L17: Set | M17: DT_OTP | O17: Y
A18: N | B18: =COUNTA($C$2:C18) -> 15 | C18: Click Verify | G18: DT_Scenario | I18: xpath | J18: //button[contains(.,'VERIFY')] | K18: 0 | L18: Click | O18: Y
A19: N | B19: =COUNTA($C$2:C19) -> 16 | C19: Wait | G19: DT_Scenario | L19: Wait | M19: 12
A20: GET A QUOTE
A21: Y | B21: =COUNTA($C$2:C21) -> 17 | C21: Select Trip Type | G21: DT_Scenario | I21: xpath | J21: ="//input[@value='"&M21&"']" -> //input[@value='DT_TripType'] | K21: 0 | L21: Tick | M21: DT_TripType
A22: Y | B22: =COUNTA($C$2:C22) -> 18 | C22: Wait | G22: DT_Scenario | L22: Wait | M22: 1
A23: Y | B23: =COUNTA($C$2:C23) -> 19 | C23: Enter Age of Primary Insured | G23: DT_Scenario | I23: xpath | J23: //input[@name='insuredAge'] | K23: 0 | L23: Set | M23: DT_PrimaryAge
A24: Y | B24: =COUNTA($C$2:C24) -> 20 | C24: Get number of additional travelers (if any) | G24: DT_Scenario | L24: Wait | M24: 1 | R24: DT_TravelersCount
A25: =IF($R$24>"0","Y","N") -> Y | B25: =COUNTA($C$2:C25) -> 21 | C25: Enter age of Traveler 1 | G25: DT_Scenario | I25: xpath | J25: //input[@name='insuredAge'] | K25: 1 | L25: Set | M25: DT_Age_TR1
A26: =IF($R$24>"1","Y","N") -> Y | B26: =COUNTA($C$2:C26) -> 22 | C26: Click Add button | G26: DT_Scenario | I26: xpath | J26: //button[@class='cmp-repeatable-container--addButton'] | K26: 0 | L26: JS_Click
A27: =A26 -> Y | B27: =COUNTA($C$2:C27) -> 23 | C27: Wait | G27: DT_Scenario | L27: Wait | M27: 1
A28: =A26 -> Y | B28: =COUNTA($C$2:C28) -> 24 | C28: Enter age of Traveler 2 | G28: DT_Scenario | I28: xpath | J28: //input[@name='insuredAge'] | K28: 2 | L28: Set | M28: DT_Age_TR2
A29: =IF($R$24>"2","Y","N") -> Y | B29: =COUNTA($C$2:C29) -> 25 | C29: Click Add button | G29: DT_Scenario | I29: xpath | J29: //button[@class='cmp-repeatable-container--addButton'] | K29: 0 | L29: JS_Click
A30: =A29 -> Y | B30: =COUNTA($C$2:C30) -> 26 | C30: Wait | G30: DT_Scenario | L30: Wait | M30: 1
A31: =A29 -> Y | B31: =COUNTA($C$2:C31) -> 27 | C31: Enter age of Traveler 3 | G31: DT_Scenario | I31: xpath | J31: //input[@name='insuredAge'] | K31: 3 | L31: Set | M31: DT_Age_TR3
A32: =IF($R$24>"3","Y","N") -> Y | B32: =COUNTA($C$2:C32) -> 28 | C32: Click Add button | G32: DT_Scenario | I32: xpath | J32: //button[@class='cmp-repeatable-container--addButton'] | K32: 0 | L32: JS_Click
A33: =A32 -> Y | B33: =COUNTA($C$2:C33) -> 29 | C33: Wait | G33: DT_Scenario | L33: Wait | M33: 1
A34: =A32 -> Y | B34: =COUNTA($C$2:C34) -> 30 | C34: Enter age of Traveler 4 | G34: DT_Scenario | I34: xpath | J34: //input[@name='insuredAge'] | K34: 4 | L34: Set | M34: DT_Age_TR4
A35: =IF($R$24>"4","Y","N") -> Y | B35: =COUNTA($C$2:C35) -> 31 | C35: Click Add button | G35: DT_Scenario | I35: xpath | J35: //button[@class='cmp-repeatable-container--addButton'] | K35: 0 | L35: JS_Click
A36: =A35 -> Y | B36: =COUNTA($C$2:C36) -> 32 | C36: Wait | G36: DT_Scenario | L36: Wait | M36: 1
A37: =A35 -> Y | B37: =COUNTA($C$2:C37) -> 33 | C37: Enter age of Traveler 5 | G37: DT_Scenario | I37: xpath | J37: //input[@name='insuredAge'] | K37: 5 | L37: Set | M37: DT_Age_TR5
A38: =IF($R$24>"5","Y","N") -> Y | B38: =COUNTA($C$2:C38) -> 34 | C38: Click Add button | G38: DT_Scenario | I38: xpath | J38: //button[@class='cmp-repeatable-container--addButton'] | K38: 0 | L38: JS_Click
A39: =A38 -> Y | B39: =COUNTA($C$2:C39) -> 35 | C39: Wait | G39: DT_Scenario | L39: Wait | M39: 1
A40: =A38 -> Y | B40: =COUNTA($C$2:C40) -> 36 | C40: Enter age of Traveler 6 | G40: DT_Scenario | I40: xpath | J40: //input[@name='insuredAge'] | K40: 6 | L40: Set | M40: DT_Age_TR6
...

Sheet Qantas_PROD_Params
A1: blnExecute | B1: DT_URL | C1: DT_Scenario | D1: Quote_OUT | E1: DT_TripType | F1: DT_Country | G1: DT_Country_2 | H1: DT_Country_3 | I1: DT_Username_IN | J1: DT_Password_IN | K1: DT_Key | L1: DT_MemoText_IN | M1: DT_PolicyNumber_IN | N1: DT_LastName_IN | O1: EMC Scenario | P1: Login Scenario | Q1: DT_ValidateQFF | R1: DT_Login_MemberNo | S1: DT_Login_Lastname | T1: DT_Login_PIN | U1: DT_OTP | V1: DT_DepartureDT | W1: DT_ReturnDT | X1: DT_PrimaryAge | Y1: DT_MemDateofBirth | Z1: DT_TravelersCount | AA1: DT_MemFirstNameTR1 | AB1: DT_MemLastNameTR1 | AC1: DT_Age_TR1 | AD1: DT_MemDateofBirthTR1 | AE1: DT_MemFirstNameTR2 | AF1: DT_MemLastNameTR2 | AG1: DT_Age_TR2 | AH1: DT_MemDateofBirthTR2 | AI1: DT_MemFirstNameTR3 | AJ1: DT_MemLastNameTR3 | AK1: DT_Age_TR3 | AL1: DT_MemDateofBirthTR3 | AM1: DT_MemFirstNameTR4 | AN1: DT_MemLastNameTR4 | AO1: DT_Age_TR4 | AP1: DT_MemDateofBirthTR4 | AQ1: DT_MemFirstNameTR5 | AR1: DT_MemLastNameTR5 | AS1: DT_Age_TR5 | AT1: DT_MemDateofBirthTR5 | AU1: DT_MemFirstNameTR6 | AV1: DT_MemLastNameTR6 | AW1: DT_Age_TR6 | AX1: DT_MemDateofBirthTR6 | AY1: DT_MemFirstNameTR7 | AZ1: DT_MemLastNameTR7 | BA1: DT_Age_TR7 | BB1: DT_MemDateofBirthTR7 | BC1: DT_MemFirstNameTR8 | BD1: DT_MemLastNameTR8 | BE1: DT_Age_TR8 | BF1: DT_MemDateofBirthTR8 | BG1: DT_MemFirstNameTR9 | BH1: DT_MemLastNameTR9 | BI1: DT_Age_TR9 | BJ1: DT_MemDateofBirthTR9 | BK1: bln_EMC5 | BL1: bln_EMC6 | BM1: bln_EMC7 | BN1: bln_EMC8 | BO1: bln_EMC9 | BP1: DT_EMCQ1 | BQ1: DT_EMCQ2 | BR1: DT_EMCQ3 | BS1: DT_EMCQ4 | BT1: DT_EMCQ5 | BU1: DT_EMCQ6 | BV1: DT_EMCQ7 | BW1: DT_EMCQ8 | BX1: DT_EMCQ9 | BY1: DT_EMCQ10 | BZ1: DT_EMCQ11 | CA1: DT_EMCQ12 | CB1: DT_EMCQ13 | CC1: DT_EMCQ14 | CD1: DT_EMCQ15 | CE1: DT_MemberNum | CF1: DT_MemberLastNm | CG1: DT_MemberPIN | CH1: DT_PolicyType | CI1: DT_BasePoints | CJ1: DT_SnowSports | CK1: DT_SpecifiedItems | CL1: DT_SpecItemsCount | CM1: DT_SpecItem1 | CN1: DT_SpecItemVal1 | CO1: DT_SpecItemDescr1 | CP1: DT_SpecItem2 | CQ1: DT_SpecItemVal2 | CR1: DT_SpecItemDescr2 | CS1: DT_SpecItem3 | CT1: DT_SpecItemVal3 | CU1: DT_SpecItemDescr3 | CV1: DT_SpecItem4 | CW1: DT_SpecItemVal4 | CX1: DT_SpecItemDescr4 | CY1: DT_SpecItem5 | CZ1: DT_SpecItemVal5 | DA1: DT_SpecItemDescr5 | DB1: DT_MemFirstName | DC1: DT_MemLastName | DD1: DT_MemEmail | DE1: DT_MemConfirmEmail | DF1: DT_MemPhoneNumber | DG1: DT_MemAddress1 | DH1: DT_MemAddress2 | DI1: DT_MemCity | DJ1: DT_MemState | DK1: DT_MemPostalCode | DL1: DT_MemCountry | DM1: DT_MemCCName | DN1: DT_MemCCExpDt | DO1: DT_MemCVV | DP1: DT_MemCCNumber | DQ1: DT_ErrorMsg_Out | DR1: PDSSavePath | DS1: TMDSavePath
A2: Y | B2: https://travel.insurance.qantas.com/ | C2: Standalone - PROD | E2: Single Trip | F2: ALBANIA | G2: ECUADOR | H2: NEW ZEALAND | I2: =VLOOKUP(Global!$B$2,Global!$E$1:$H$4,3,FALSE) -> https://api.uat.travelguard.com/policy/v4/ | J2: =VLOOKUP(Global!$B$2,Global!$E$1:$H$4,4,FALSE) -> https://agents.uat.travelguard.com/content/tg-agents/qantas/en/login.html | K2: M23WSADEB65Y5A6J | L2: Test Memo 07282023134349 | M2: 1253229296 | N2: test102024 | O2: EMC7 | Q2: N | R2: 2005277013 | S2: Flytest | T2: 1717 | U2: 123456 | V2: =TEXT(TODAY()+1,"DD/MM/YYYY") -> 19/05/2026 | W2: =TEXT(TODAY()+8,"DD/MM/YYYY") -> 26/05/2026 | X2: 35 | Y2: =TEXT(DATE(YEAR(TODAY())-X2,MONTH(TODAY()),DAY(TODAY())),"DD/MM/YYYY") -> 18/05/1991 | Z2: 0 | AA2: ="Travone"&CHAR(RANDBETWEEN(65,90))&CHAR(RANDBETWEEN(65,90))&CHAR(RANDBETWEEN(65,90)) -> TravoneGCU | AB2: Test | AD2: =TEXT(DATE(YEAR(TODAY())-AC2,MONTH(TODAY()),DAY(TODAY())),"DD/MM/YYYY") -> 18/05/2026 | AE2: ="Travtwo"&CHAR(RANDBETWEEN(65,90))&CHAR(RANDBETWEEN(65,90))&CHAR(RANDBETWEEN(65,90)) -> TravtwoFEA | AF2: Test | AH2: =TEXT(DATE(YEAR(TODAY())-AG2,MONTH(TODAY()),DAY(TODAY())),"DD/MM/YYYY") -> 18/05/2026 | AI2: ="Travthree"&CHAR(RANDBETWEEN(65,90))&CHAR(RANDBETWEEN(65,90))&CHAR(RANDBETWEEN(65,90)) -> TravthreeTCE | AJ2: Test | AL2: =TEXT(DATE(YEAR(TODAY())-AK2,MONTH(TODAY()),DAY(TODAY())),"DD/MM/YYYY") -> 18/05/2026 | AM2: ="Travfour"&CHAR(RANDBETWEEN(65,90))&CHAR(RANDBETWEEN(65,90))&CHAR(RANDBETWEEN(65,90)) -> TravfourAYK | AN2: Last | AP2: =TEXT(DATE(YEAR(TODAY())-AO2,MONTH(TODAY()),DAY(TODAY())),"DD/MM/YYYY") -> 18/05/2026 | AQ2: ="Travfive"&CHAR(RANDBETWEEN(65,90))&CHAR(RANDBETWEEN(65,90))&CHAR(RANDBETWEEN(65,90)) -> TravfiveLKI | AR2: Last | AT2: =TEXT(DATE(YEAR(TODAY())-AS2,MONTH(TODAY()),DAY(TODAY())),"DD/MM/YYYY") -> 18/05/2026 | AU2: ="Travsix"&CHAR(RANDBETWEEN(65,90))&CHAR(RANDBETWEEN(65,90))&CHAR(RANDBETWEEN(65,90)) -> TravsixXJH | AV2: Last | AX2: =TEXT(DATE(YEAR(TODAY())-AW2,MONTH(TODAY()),DAY(TODAY())),"DD/MM/YYYY") -> 18/05/2026 | AY2: ="Travseven"&CHAR(RANDBETWEEN(65,90))&CHAR(RANDBETWEEN(65,90))&CHAR(RANDBETWEEN(65,90)) -> TravsevenJCB | AZ2: Last | BB2: =TEXT(DATE(YEAR(TODAY())-BA2,MONTH(TODAY()),DAY(TODAY())),"DD/MM/YYYY") -> 18/05/2026 | BC2: ="Traveight"&CHAR(RANDBETWEEN(65,90))&CHAR(RANDBETWEEN(65,90))&CHAR(RANDBETWEEN(65,90)) -> TraveightWWY | BD2: Last | BF2: =TEXT(DATE(YEAR(TODAY())-BE2,MONTH(TODAY()),DAY(TODAY())),"DD/MM/YYYY") -> 18/05/2026 | BG2: ="Travnine"&CHAR(RANDBETWEEN(65,90))&CHAR(RANDBETWEEN(65,90))&CHAR(RANDBETWEEN(65,90)) -> TravnineZWP | BH2: Last | BJ2: =TEXT(DATE(YEAR(TODAY())-BI2,MONTH(TODAY()),DAY(TODAY())),"DD/MM/YYYY") -> 18/05/2026 | BM2: Y | BP2: YES | BQ2: NO | BR2: YES | BS2: NO | BT2: NO | BU2: NO | BV2: NO | BW2: Asthma | BX2: One | BY2: Yes | BZ2: Chest infection | CA2: Yes | CB2: Yes | CC2: One | CD2: No | CH2: International Comprehensive | CI2: =IF(CH2="Australian Comprehensive",150,IF(CH2="International Comprehensive",2000,IF(CH2="Annual Multi Trip",7000,"invalid"))) -> 2000 | CJ2: Y | CK2: N | CL2: 0 | DB2: ="QATestFName"&CHAR(RANDBETWEEN(69,80))&CHAR(RANDBETWEEN(69,80))&CHAR(RANDBETWEEN(69,80))&RANDBETWEEN(111,999) -> QATestFNameEJM619 | DC2: ="QATestLName"&CHAR(RANDBETWEEN(69,80))&CHAR(RANDBETWEEN(69,80))&CHAR(RANDBETWEEN(69,80))&RANDBETWEEN(111,999) -> QATestLNameFMP827 | DD2: florence.loquinario@aig.com | DE2: florence.loquinario@aig.com | DF2: 9876543210 | DG2: Test Address1 | DH2: Address2 | DI2: Test City | DJ2: Victoria | DK2: 876543 | DL2: AU | DM2: QA Test | DN2: 122029 | DO2: =""&RANDBETWEEN(111,999) -> 977 | DP2: 5577810000000004 | DR2: =Global!$C$19&C2&"Standalone_PDS.pdf" -> L:\Regression\Test Results\Temp_Results\AEM Regression\Qantas\UAT\Qantas StandAlone - Staff Daily Regression_2026-May-18-1215_23\Standalone - PRODStandalone_PDS.pdf | DS2: =Global!$C$19&C2&"Standalone_TMD.pdf" -> L:\Regression\Test Results\Temp_Results\AEM Regression\Qantas\UAT\Qantas StandAlone - Staff Daily Regression_2026-May-18-1215_23\Standalone - PRODStandalone_TMD.pdf
R5: Alternative Users
R7: 2005276767 | S7: locked
R8: Flytest
R9: 1717
R11: 2005276874
R12: Lava
R13: 1717
R15: 2005276957
R16: Flytest
R17: 1717
R19: 2005277013
R20: Flytest
R21: 1717

Sheet Qantas
A1: blnExecute | B1: Step_Number | C1: Step_Name | D1: Status | E1: Error_Check | F1: breakpoint | G1: Test_Case | H1: Page | I1: FindBy | J1: FindBy_Value | K1: Index | L1: Method | M1: Value | N1: Output_Property | O1: Ignore_not_existing_object | P1: isDisabled | Q1: Timeout | R1: Expected_Value | S1: Output_Value | T1: Exact_Match | U1: Contains | V1: Notes | W1: Start_Time | X1: End_Time | Y1: Duration
A2: Open Site
A3: Y | B3: =COUNTA($C$2:C3) -> 1 | C3: Launch Site | G3: DT_Scenario | H3: chrome | K3: 0 | L3: Open | M3: DT_URL
A4: N | B4: =COUNTA($C$2:C4) -> 2 | C4: Wait | G4: DT_Scenario | L4: Wait | M4: 10
A5: N | B5: =COUNTA($C$2:C5) -> 3 | C5: Zscaler Sign in Email | G5: DT_Scenario | I5: xpath | J5: //input[@id='okta-signin-username'] | K5: 0 | L5: Set | M5: DT_ZScalerUser | O5: Y | Q5: 5
A6: N | B6: =COUNTA($C$2:C6) -> 4 | C6: Zscaler Password | G6: DT_Scenario | I6: xpath | J6: //input[@id='okta-signin-password'] | K6: 0 | L6: Set | M6: DT_ZScalerPassword | O6: Y
A7: N | B7: =COUNTA($C$2:C7) -> 5 | C7: Click Sign in | G7: DT_Scenario | I7: xpath | J7: //input[@id='okta-signin-submit'] | K7: 0 | L7: Click | O7: Y
A8: N | B8: =COUNTA($C$2:C8) -> 6 | C8: Wait | G8: DT_Scenario | L8: Wait | M8: 5
A9: Qantas Purchase Path
A10: Y | B10: =COUNTA($C$2:C10) -> 7 | C10: Click Login Icon | G10: DT_Scenario | I10: xpath | J10: //span[contains(.,'Log in')] | K10: 0 | L10: Click
A11: Y | B11: =COUNTA($C$2:C11) -> 8 | C11: Wait | G11: DT_Scenario | L11: Wait | M11: 5
A12: Y | B12: =COUNTA($C$2:C12) -> 9 | C12: Enter Membership Number | G12: DT_Scenario | I12: xpath | J12: //input[@name='memberId'] | K12: 0 | L12: Set | M12: DT_Login_MemberNo
A13: Y | B13: =COUNTA($C$2:C13) -> 10 | C13: Enter Last Name | G13: DT_Scenario | I13: xpath | J13: //input[@name='lastName'] | K13: 0 | L13: Set | M13: DT_Login_Lastname
A14: Y | B14: =COUNTA($C$2:C14) -> 11 | C14: Enter PIN | G14: DT_Scenario | I14: xpath | J14: //input[@name='pin'] | K14: 0 | L14: Set | M14: DT_Login_PIN
A15: Y | B15: =COUNTA($C$2:C15) -> 12 | C15: Click Login | G15: DT_Scenario | I15: xpath | J15: //button[contains(.,'LOG IN')] | K15: 0 | L15: Click
A16: Y | B16: =COUNTA($C$2:C16) -> 13 | C16: Wait | G16: DT_Scenario | L16: Wait | M16: 7
A17: Answer Security Questions Verification
A18: =IF(Global!B2="UAT"," Y","N") -> Y | B18: =COUNTA($C$2:C18) -> 14 | C18: Select other options | G18: DT_Scenario | I18: xpath | J18: //span[contains(.,'See options')] | K18: 1 | L18: Click
A19: =A18 -> Y | B19: =COUNTA($C$2:C19) -> 15 | C19: Wait | G19: DT_Scenario | L19: Wait | M19: 5
A20: =A18 -> Y | B20: =COUNTA($C$2:C20) -> 16 | C20: Select Security Questions | G20: DT_Scenario | I20: xpath | J20: //div[contains(.,'Answer security questions')] | K20: 8 | L20: Click
A21: =A20 -> Y | B21: =COUNTA($C$2:C21) -> 17 | C21: Wait | G21: DT_Scenario | L21: Wait | M21: 5
A22: =A20 -> Y | B22: =COUNTA($C$2:C22) -> 18 | C22: Input Maiden Name | G22: DT_Scenario | I22: xpath | J22: //input[@id='mfa-psq-mothers-maiden-name'] | K22: 0 | L22: Set | M22: DT_Maiden
B23: =COUNTA($C$2:C23) -> 19 | C23: Toggle DoB Day | G23: DT_Scenario | I23: xpath | J23: (//select[@class='focus:outline-0 focus:border-[#8de2e0] border-2 h-9 w-1/4'])[1] | K23: 0 | L23: Click
A24: =A22 -> Y | B24: =COUNTA($C$2:C24) -> 20 | C24: Select DoB Day | G24: DT_Scenario | I24: xpath | J24: ="//select//option[@value='"&M24&"']" -> //select//option[@value='DT_DoB_Day'] | K24: 0 | L24: Click | M24: DT_DoB_Day
B25: =COUNTA($C$2:C25) -> 21 | C25: Toggle DoB Month | G25: DT_Scenario | I25: xpath | J25: (//div[@class='focus:outline-0 focus:border-[#8de2e0] border-2 h-9 w-1/3'])[2] | K25: 0 | L25: Click
A26: =A24 -> Y | B26: =COUNTA($C$2:C26) -> 22 | C26: Select DoB Month | G26: DT_Scenario | I26: xpath | J26: ="//select//option[contains(.,'"&M26&"')]" -> //select//option[contains(.,'DT_DoB_Month')] | K26: 0 | L26: Click | M26: DT_DoB_Month
B27: =COUNTA($C$2:C27) -> 23 | C27: Toggle DoB Year | G27: DT_Scenario | I27: xpath | J27: (//div[@class='focus:outline-0 focus:border-[#8de2e0] border-2 h-9 w-1/4'])[3] | K27: 0 | L27: Click
A28: =A26 -> Y | B28: =COUNTA($C$2:C28) -> 24 | C28: Select DoB Year | G28: DT_Scenario | I28: xpath | J28: ="//select//option[contains(.,'"&M28&"')]" -> //select//option[contains(.,'DT_DoB_Year')] | K28: 0 | L28: Click | M28: DT_DoB_Year
A29: =A28 -> Y | B29: =COUNTA($C$2:C29) -> 25 | C29: Input Postal Code | G29: DT_Scenario | I29: xpath | J29: //input[@id='mfa-psq-postcode'] | K29: 0 | L29: Set | M29: DT_PostalCode
B30: =COUNTA($C$2:C30) -> 26 | C30: Toggle Join Month | G30: DT_Scenario | I30: xpath | J30: (//div[@class='focus:outline-0 focus:border-[#8de2e0] border-2 h-9 w-1/3'])[4] | K30: 0 | L30: Click
A31: =A22 -> Y | B31: =COUNTA($C$2:C31) -> 27 | C31: Input Join Month | G31: DT_Scenario | I31: xpath | J31: ="//select//option[contains(.,'"&M31&"')]" -> //select//option[contains(.,'DT_JoinMonth')] | K31: 1 | L31: Click | M31: DT_JoinMonth
B32: =COUNTA($C$2:C32) -> 28 | C32: Toggle Join Year | G32: DT_Scenario | I32: xpath | J32: (//div[@class='focus:outline-0 focus:border-[#8de2e0] border-2 h-9 w-1/3'])[5] | K32: 0 | L32: Click
A33: =A31 -> Y | B33: =COUNTA($C$2:C33) -> 29 | C33: Input Join Year | G33: DT_Scenario | I33: xpath | J33: ="//select//option[contains(.,'"&M33&"')]" -> //select//option[contains(.,'DT_JoinYear')] | K33: 1 | L33: Click | M33: DT_JoinYear
A34: =A33 -> Y | B34: =COUNTA($C$2:C34) -> 30 | C34: Click Verify | G34: DT_Scenario | I34: xpath | J34: //button[contains(.,'VERIFY')] | K34: 0 | L34: Click | O34: Y
A35: Y | B35: =COUNTA($C$2:C35) -> 31 | C35: Wait | G35: DT_Scenario | L35: Wait | M35: 5
A36: Close Browser
B37: =COUNTA($C$2:C37) -> 32 | C37: Quit | G37: DT_Scenario | L37: Quit
B38: =COUNTA($C$2:C38) -> 33 | C38: Break | G38: DT_Scenario | L38: Break
A40: =IF(Global!B2="UAT"," N","Y") -> N | B40: =COUNTA($C$2:C40) -> 34 | C40: Enter Verification | G40: DT_Scenario | I40: xpath | J40: //input[@name='verifyCode'] | K40: 0 | L40: Set | M40: DT_OTP | O40: Y
A41: =A40 -> N | B41: =COUNTA($C$2:C41) -> 35 | C41: Click Verify | G41: DT_Scenario | I41: xpath | J41: //button[contains(.,'VERIFY')] | K41: 0 | L41: Click | O41: Y
...

Sheet Qantas_Params
A1: blnExecute | B1: DT_URL | C1: DT_Scenario | D1: DT_Policy_Out | E1: DT_TripType | F1: DT_Country | G1: DT_Country_2 | H1: DT_Country_3 | I1: DT_Username_IN | J1: DT_Password_IN | K1: DT_Key | L1: DT_MemoText_IN | M1: DT_PolicyNumber_IN | N1: DT_LastName_IN | O1: EMC Scenario | P1: Login Scenario | Q1: DT_ValidateQFF | R1: DT_Login_MemberNo | S1: DT_Login_Lastname | T1: DT_Login_PIN | U1: DT_OTP | V1: DT_Maiden | W1: DT_DoB_Day | X1: DT_DoB_Month | Y1: DT_DoB_Year | Z1: DT_PostalCode | AA1: DT_JoinMonth | AB1: DT_JoinYear | AC1: DT_DepartureDT | AD1: DT_ReturnDT | AE1: DT_PrimaryAge | AF1: DT_MemDateofBirth | AG1: DT_TravelersCount | AH1: DT_MemFirstNameTR1 | AI1: DT_MemLastNameTR1 | AJ1: DT_Age_TR1 | AK1: DT_MemDateofBirthTR1 | AL1: DT_MemFirstNameTR2 | AM1: DT_MemLastNameTR2 | AN1: DT_Age_TR2 | AO1: DT_MemDateofBirthTR2 | AP1: DT_MemFirstNameTR3 | AQ1: DT_MemLastNameTR3 | AR1: DT_Age_TR3 | AS1: DT_MemDateofBirthTR3 | AT1: DT_MemFirstNameTR4 | AU1: DT_MemLastNameTR4 | AV1: DT_Age_TR4 | AW1: DT_MemDateofBirthTR4 | AX1: DT_MemFirstNameTR5 | AY1: DT_MemLastNameTR5 | AZ1: DT_Age_TR5 | BA1: DT_MemDateofBirthTR5 | BB1: DT_MemFirstNameTR6 | BC1: DT_MemLastNameTR6 | BD1: DT_Age_TR6 | BE1: DT_MemDateofBirthTR6 | BF1: DT_MemFirstNameTR7 | BG1: DT_MemLastNameTR7 | BH1: DT_Age_TR7 | BI1: DT_MemDateofBirthTR7 | BJ1: DT_MemFirstNameTR8 | BK1: DT_MemLastNameTR8 | BL1: DT_Age_TR8 | BM1: DT_MemDateofBirthTR8 | BN1: DT_MemFirstNameTR9 | BO1: DT_MemLastNameTR9 | BP1: DT_Age_TR9 | BQ1: DT_MemDateofBirthTR9 | BR1: bln_EMC5 | BS1: bln_EMC6 | BT1: bln_EMC7 | BU1: bln_EMC8 | BV1: bln_EMC9 | BW1: DT_EMCQ1 | BX1: DT_EMCQ2 | BY1: DT_EMCQ3 | BZ1: DT_EMCQ4 | CA1: DT_EMCQ5 | CB1: DT_EMCQ6 | CC1: DT_EMCQ7 | CD1: DT_EMCQ8 | CE1: DT_EMCQ9 | CF1: DT_EMCQ10 | CG1: DT_EMCQ11 | CH1: DT_EMCQ12 | CI1: DT_EMCQ13 | CJ1: DT_EMCQ14 | CK1: DT_EMCQ15 | CL1: DT_MemberNum | CM1: DT_MemberLastNm | CN1: DT_MemberPIN | CO1: DT_PolicyType | CP1: DT_BasePoints | CQ1: DT_SnowSports | CR1: DT_SpecifiedItems | CS1: DT_Cruise | CT1: DT_SnowSports_Staff | CU1: DT_SpecifiedItems_Staff | CV1: DT_Cruise_Staff | CW1: DT_SpecItemsCount | CX1: DT_SpecItem1 | CY1: DT_SpecItemVal1 | CZ1: DT_SpecItemDescr1 | DA1: DT_SpecItem2 | DB1: DT_SpecItemVal2 | DC1: DT_SpecItemDescr2 | DD1: DT_SpecItem3 | DE1: DT_SpecItemVal3 | DF1: DT_SpecItemDescr3 | DG1: DT_SpecItem4 | DH1: DT_SpecItemVal4 | DI1: DT_SpecItemDescr4 | DJ1: DT_SpecItem5 | DK1: DT_SpecItemVal5 | DL1: DT_SpecItemDescr5 | DM1: DT_MemFirstName | DN1: DT_MemLastName | DO1: DT_MemEmail | DP1: DT_MemConfirmEmail | DQ1: DT_MemPhoneNumber | DR1: DT_MemAddress1 | DS1: DT_MemAddress2 | DT1: DT_MemCity | DU1: DT_MemState | DV1: DT_MemPostalCode | DW1: DT_MemCountry | DX1: DT_MemCCName | DY1: DT_MemCCExpDt | DZ1: DT_MemCVV | EA1: DT_MemCCNumber | EB1: DT_ErrorMsg_Out | EC1: PDSSavePath | ED1: TMDSavePath
A2: N | B2: https://qantas.qa.travelguard.com | C2: Standalone - QA | E2: Single Trip | F2: ALBANIA | G2: ECUADOR | H2: NEW ZEALAND | I2: =VLOOKUP(Global!$B$2,Global!$E$1:$H$4,3,FALSE) -> https://api.uat.travelguard.com/policy/v4/ | J2: =VLOOKUP(Global!$B$2,Global!$E$1:$H$4,4,FALSE) -> https://agents.uat.travelguard.com/content/tg-agents/qantas/en/login.html | K2: M23WSADEB65Y5A6J | L2: Test Memo 07282023134349 | M2: 1253229296 | N2: test102024 | O2: EMC7 | Q2: N | R2: 2005277013 | S2: Flytest | T2: 1717 | U2: 123456 | AC2: =TEXT(TODAY()+1,"DD/MM/YYYY") -> 19/05/2026 | AD2: =TEXT(TODAY()+8,"DD/MM/YYYY") -> 26/05/2026 | AE2: 35 | AF2: =TEXT(DATE(YEAR(TODAY())-AE2,MONTH(TODAY()),DAY(TODAY())),"DD/MM/YYYY") -> 18/05/1991 | AG2: 2 | AH2: ="Travone"&CHAR(RANDBETWEEN(65,90))&CHAR(RANDBETWEEN(65,90))&CHAR(RANDBETWEEN(65,90)) -> TravoneMJN | AI2: Test | AJ2: 9 | AK2: =TEXT(DATE(YEAR(TODAY())-AJ2,MONTH(TODAY()),DAY(TODAY())),"DD/MM/YYYY") -> 18/05/2017 | AL2: ="Travtwo"&CHAR(RANDBETWEEN(65,90))&CHAR(RANDBETWEEN(65,90))&CHAR(RANDBETWEEN(65,90)) -> TravtwoLTO | AM2: Test | AN2: 92 | AO2: =TEXT(DATE(YEAR(TODAY())-AN2,MONTH(TODAY()),DAY(TODAY())),"DD/MM/YYYY") -> 18/05/1934 | AP2: ="Travthree"&CHAR(RANDBETWEEN(65,90))&CHAR(RANDBETWEEN(65,90))&CHAR(RANDBETWEEN(65,90)) -> TravthreeJUP | AQ2: Test | AS2: =TEXT(DATE(YEAR(TODAY())-AR2,MONTH(TODAY()),DAY(TODAY())),"DD/MM/YYYY") -> 18/05/2026 | AT2: ="Travfour"&CHAR(RANDBETWEEN(65,90))&CHAR(RANDBETWEEN(65,90))&CHAR(RANDBETWEEN(65,90)) -> TravfourAYW | AU2: Last | AW2: =TEXT(DATE(YEAR(TODAY())-AV2,MONTH(TODAY()),DAY(TODAY())),"DD/MM/YYYY") -> 18/05/2026 | AX2: ="Travfive"&CHAR(RANDBETWEEN(65,90))&CHAR(RANDBETWEEN(65,90))&CHAR(RANDBETWEEN(65,90)) -> TravfiveWBA | AY2: Last | BA2: =TEXT(DATE(YEAR(TODAY())-AZ2,MONTH(TODAY()),DAY(TODAY())),"DD/MM/YYYY") -> 18/05/2026 | BB2: ="Travsix"&CHAR(RANDBETWEEN(65,90))&CHAR(RANDBETWEEN(65,90))&CHAR(RANDBETWEEN(65,90)) -> TravsixGEO | BC2: Last | BE2: =TEXT(DATE(YEAR(TODAY())-BD2,MONTH(TODAY()),DAY(TODAY())),"DD/MM/YYYY") -> 18/05/2026 | BF2: ="Travseven"&CHAR(RANDBETWEEN(65,90))&CHAR(RANDBETWEEN(65,90))&CHAR(RANDBETWEEN(65,90)) -> TravsevenQLI | BG2: Last | BI2: =TEXT(DATE(YEAR(TODAY())-BH2,MONTH(TODAY()),DAY(TODAY())),"DD/MM/YYYY") -> 18/05/2026 | BJ2: ="Traveight"&CHAR(RANDBETWEEN(65,90))&CHAR(RANDBETWEEN(65,90))&CHAR(RANDBETWEEN(65,90)) -> TraveightSDK | BK2: Last | BM2: =TEXT(DATE(YEAR(TODAY())-BL2,MONTH(TODAY()),DAY(TODAY())),"DD/MM/YYYY") -> 18/05/2026 | BN2: ="Travnine"&CHAR(RANDBETWEEN(65,90))&CHAR(RANDBETWEEN(65,90))&CHAR(RANDBETWEEN(65,90)) -> TravnineNRH | BO2: Last | BQ2: =TEXT(DATE(YEAR(TODAY())-BP2,MONTH(TODAY()),DAY(TODAY())),"DD/MM/YYYY") -> 18/05/2026 | BT2: Y | BW2: YES | BX2: NO | BY2: YES | BZ2: NO | CA2: NO | CB2: NO | CC2: NO | CD2: Asthma | CE2: One | CF2: Yes | CG2: Chest infection | CH2: Yes | CI2: Yes | CJ2: One | CK2: No | CO2: International Comprehensive | CP2: =IF(CO2="Australian Comprehensive",100,IF(CO2="International Comprehensive",10000,IF(CO2="Annual Multi Trip",6000,"invalid"))) -> 10000 | CQ2: Y | CR2: Y | CS2: N | CT2: Y | CU2: Y | CV2: N | CW2: 5 | CX2: Sport & Leisure Equipment | CY2: 1000 | CZ2: SLE1 | DA2: Sport & Leisure Equipment | DB2: 1000 | DC2: SLE2 | DD2: Sport & Leisure Equipment | DE2: 3000 | DF2: SLE3 | DG2: Personal Computers | DH2: 7000 | DI2: PC7000 | DJ2: Other Luggage Item | DK2: 8000 | DL2: Luggage | DM2: ="QATestFName"&CHAR(RANDBETWEEN(69,80))&CHAR(RANDBETWEEN(69,80))&CHAR(RANDBETWEEN(69,80))&RANDBETWEEN(111,999) -> QATestFNameJIO441 | DN2: ="QATestLName"&CHAR(RANDBETWEEN(69,80))&CHAR(RANDBETWEEN(69,80))&CHAR(RANDBETWEEN(69,80))&RANDBETWEEN(111,999) -> QATestLNameHGE292 | DO2: qa@test.com | DP2: qa@test.com | DQ2: 9876543210 | DR2: Test Address1 | DS2: Address2 | DT2: Test City | DU2: Victoria | DV2: 876543 | DW2: AU | DX2: QA Test | DY2: 032030 | DZ2: 737 | EA2: 5555341244441115 | EC2: =Global!$C$19&C2&"Standalone_PDS.pdf" -> L:\Regression\Test Results\Temp_Results\AEM Regression\Qantas\UAT\Qantas StandAlone - Staff Daily Regression_2026-May-18-1215_23\Standalone - QAStandalone_PDS.pdf | ED2: =Global!$C$19&C2&"Standalone_TMD.pdf" -> L:\Regression\Test Results\Temp_Results\AEM Regression\Qantas\UAT\Qantas StandAlone - Staff Daily Regression_2026-May-18-1215_23\Standalone - QAStandalone_TMD.pdf
A3: Y | B3: https://qantas.uat.travelguard.com | C3: Standalone - UAT | E3: Annual Multi Trip | F3: ALBANIA | G3: ECUADOR | H3: NEW ZEALAND | I3: =VLOOKUP(Global!$B$2,Global!$E$1:$H$4,3,FALSE) -> https://api.uat.travelguard.com/policy/v4/ | J3: =VLOOKUP(Global!$B$2,Global!$E$1:$H$4,4,FALSE) -> https://agents.uat.travelguard.com/content/tg-agents/qantas/en/login.html | K3: M23WSADEB65Y5A6J | L3: Test Memo 07282023134349 | M3: 1253229296 | N3: test102024 | O3: EMC7 | Q3: N | R3: 1979970702 | S3: Loytest | T3: 1717 | V3: Mum | W3: 01 | X3: January | Y3: 2001 | Z3: 2020 | AA3: July | AB3: 2024 | AC3: =TEXT(TODAY()+1,"DD/MM/YYYY") -> 19/05/2026 | AD3: =TEXT(TODAY()+2,"DD/MM/YYYY") -> 20/05/2026 | AE3: 25 | AF3: =TEXT(DATE(YEAR(TODAY())-AE3,MONTH(TODAY()),DAY(TODAY())),"DD/MM/YYYY") -> 18/05/2001 | AG3: 2 | AH3: ="Travone"&CHAR(RANDBETWEEN(65,90))&CHAR(RANDBETWEEN(65,90))&CHAR(RANDBETWEEN(65,90)) -> TravoneTQM | AI3: Test | AJ3: 80 | AK3: =TEXT(DATE(YEAR(TODAY())-AJ3,MONTH(TODAY()),DAY(TODAY())),"DD/MM/YYYY") -> 18/05/1946 | AL3: ="Travtwo"&CHAR(RANDBETWEEN(65,90))&CHAR(RANDBETWEEN(65,90))&CHAR(RANDBETWEEN(65,90)) -> TravtwoMIH | AM3: Test | AN3: 6 | AO3: =TEXT(DATE(YEAR(TODAY())-AN3,MONTH(TODAY()),DAY(TODAY())),"DD/MM/YYYY") -> 18/05/2020 | AP3: ="Travthree"&CHAR(RANDBETWEEN(65,90))&CHAR(RANDBETWEEN(65,90))&CHAR(RANDBETWEEN(65,90)) -> TravthreeUPA | AQ3: Test | AS3: =TEXT(DATE(YEAR(TODAY())-AR3,MONTH(TODAY()),DAY(TODAY())),"DD/MM/YYYY") -> 18/05/2026 | AT3: ="Travfour"&CHAR(RANDBETWEEN(65,90))&CHAR(RANDBETWEEN(65,90))&CHAR(RANDBETWEEN(65,90)) -> TravfourKOY | AU3: Last | AW3: =TEXT(DATE(YEAR(TODAY())-AV3,MONTH(TODAY()),DAY(TODAY())),"DD/MM/YYYY") -> 18/05/2026 | AX3: ="Travfive"&CHAR(RANDBETWEEN(65,90))&CHAR(RANDBETWEEN(65,90))&CHAR(RANDBETWEEN(65,90)) -> TravfiveZMK | AY3: Last | BA3: =TEXT(DATE(YEAR(TODAY())-AZ3,MONTH(TODAY()),DAY(TODAY())),"DD/MM/YYYY") -> 18/05/2026 | BB3: ="Travsix"&CHAR(RANDBETWEEN(65,90))&CHAR(RANDBETWEEN(65,90))&CHAR(RANDBETWEEN(65,90)) -> TravsixKPB | BC3: Last | BE3: =TEXT(DATE(YEAR(TODAY())-BD3,MONTH(TODAY()),DAY(TODAY())),"DD/MM/YYYY") -> 18/05/2026 | BF3: ="Travseven"&CHAR(RANDBETWEEN(65,90))&CHAR(RANDBETWEEN(65,90))&CHAR(RANDBETWEEN(65,90)) -> TravsevenWME | BG3: Last | BI3: =TEXT(DATE(YEAR(TODAY())-BH3,MONTH(TODAY()),DAY(TODAY())),"DD/MM/YYYY") -> 18/05/2026 | BJ3: ="Traveight"&CHAR(RANDBETWEEN(65,90))&CHAR(RANDBETWEEN(65,90))&CHAR(RANDBETWEEN(65,90)) -> TraveightIXA | BK3: Last | BM3: =TEXT(DATE(YEAR(TODAY())-BL3,MONTH(TODAY()),DAY(TODAY())),"DD/MM/YYYY") -> 18/05/2026 | BN3: ="Travnine"&CHAR(RANDBETWEEN(65,90))&CHAR(RANDBETWEEN(65,90))&CHAR(RANDBETWEEN(65,90)) -> TravninePEQ | BO3: Last | BQ3: =TEXT(DATE(YEAR(TODAY())-BP3,MONTH(TODAY()),DAY(TODAY())),"DD/MM/YYYY") -> 18/05/2026 | BT3: Y | BW3: YES | BX3: NO | BY3: YES | BZ3: NO | CA3: NO | CB3: NO | CC3: NO | CD3: Asthma | CE3: One | CF3: Yes | CG3: Chest infection | CH3: Yes | CI3: Yes | CJ3: One | CK3: No | CO3: Annual Multi Trip | CP3: =IF(CO3="Australian Comprehensive",100,IF(CO3="International Comprehensive",1000,IF(CO3="Annual Multi Trip",10000,"invalid"))) -> 10000 | CQ3: Yes | CR3: No | CS3: No | CT3: Yes | CU3: No | CV3: No | CW3: 5 | CX3: Sport & Leisure Equipment | CY3: 1000 | CZ3: SLE1 | DA3: Sport & Leisure Equipment | DB3: 1000 | DC3: SLE2 | DD3: Sport & Leisure Equipment | DE3: 3000 | DF3: SLE3 | DG3: Personal Computers | DH3: 7000 | DI3: PC7000 | DJ3: Other Luggage Item | DK3: 8000 | DL3: Luggage | DM3: ="QATestFName"&CHAR(RANDBETWEEN(69,80))&CHAR(RANDBETWEEN(69,80))&CHAR(RANDBETWEEN(69,80))&RANDBETWEEN(111,999) -> QATestFNameMHK947 | DN3: ="QATestLName"&CHAR(RANDBETWEEN(69,80))&CHAR(RANDBETWEEN(69,80))&CHAR(RANDBETWEEN(69,80))&RANDBETWEEN(111,999) -> QATestLNameIGF262 | DO3: qa@test.com | DP3: qa@test.com | DQ3: 9876543210 | DR3: Test Address1 | DS3: Address2 | DT3: Test City | DU3: Victoria | DV3: 876543 | DW3: AU | DX3: QA Test | DY3: 032030 | DZ3: 737 | EA3: 5555341244441115 | EC3: =Global!$C$19&C3&"Standalone_PDS.pdf" -> L:\Regression\Test Results\Temp_Results\AEM Regression\Qantas\UAT\Qantas StandAlone - Staff Daily Regression_2026-May-18-1215_23\Standalone - UATStandalone_PDS.pdf | ED3: =Global!$C$19&C3&"Standalone_TMD.pdf" -> L:\Regression\Test Results\Temp_Results\AEM Regression\Qantas\UAT\Qantas StandAlone - Staff Daily Regression_2026-May-18-1215_23\Standalone - UATStandalone_TMD.pdf
A4: N | B4: =B2&"/employee/home" -> https://qantas.qa.travelguard.com/employee/home | C4: Staff - QA | E4: Single Trip | F4: ALBANIA | G4: ECUADOR | H4: NEW ZEALAND | I4: =VLOOKUP(Global!$B$2,Global!$E$1:$H$4,3,FALSE) -> https://api.uat.travelguard.com/policy/v4/ | J4: =VLOOKUP(Global!$B$2,Global!$E$1:$H$4,4,FALSE) -> https://agents.uat.travelguard.com/content/tg-agents/qantas/en/login.html | K4: M23WSADEB65Y5A6J | L4: Test Memo 07282023134349 | M4: 1253229296 | N4: test102024 | O4: EMC7 | Q4: N | R4: 2005276957 | S4: Flytest | T4: 1717 | U4: 123456 | AC4: =TEXT(TODAY()+1,"DD/MM/YYYY") -> 19/05/2026 | AD4: =TEXT(TODAY()+15,"DD/MM/YYYY") -> 02/06/2026 | AE4: 67 | AF4: =TEXT(DATE(YEAR(TODAY())-AE4,MONTH(TODAY()),DAY(TODAY())),"DD/MM/YYYY") -> 18/05/1959 | AG4: 2 | AH4: ="Travone"&CHAR(RANDBETWEEN(65,90))&CHAR(RANDBETWEEN(65,90))&CHAR(RANDBETWEEN(65,90)) -> TravoneMKZ | AI4: Test | AJ4: 28 | AK4: =TEXT(DATE(YEAR(TODAY())-AJ4,MONTH(TODAY()),DAY(TODAY())),"DD/MM/YYYY") -> 18/05/1998 | AL4: ="Travtwo"&CHAR(RANDBETWEEN(65,90))&CHAR(RANDBETWEEN(65,90))&CHAR(RANDBETWEEN(65,90)) -> TravtwoTVT | AM4: Test | AN4: 10 | AO4: =TEXT(DATE(YEAR(TODAY())-AN4,MONTH(TODAY()),DAY(TODAY())),"DD/MM/YYYY") -> 18/05/2016 | AP4: ="Travthree"&CHAR(RANDBETWEEN(65,90))&CHAR(RANDBETWEEN(65,90))&CHAR(RANDBETWEEN(65,90)) -> TravthreeKGS | AQ4: Test | AS4: =TEXT(DATE(YEAR(TODAY())-AR4,MONTH(TODAY()),DAY(TODAY())),"DD/MM/YYYY") -> 18/05/2026 | AT4: ="Travfour"&CHAR(RANDBETWEEN(65,90))&CHAR(RANDBETWEEN(65,90))&CHAR(RANDBETWEEN(65,90)) -> TravfourSKU | AU4: Last | AW4: =TEXT(DATE(YEAR(TODAY())-AV4,MONTH(TODAY()),DAY(TODAY())),"DD/MM/YYYY") -> 18/05/2026 | AX4: ="Travfive"&CHAR(RANDBETWEEN(65,90))&CHAR(RANDBETWEEN(65,90))&CHAR(RANDBETWEEN(65,90)) -> TravfiveYJL | AY4: Last | BA4: =TEXT(DATE(YEAR(TODAY())-AZ4,MONTH(TODAY()),DAY(TODAY())),"DD/MM/YYYY") -> 18/05/2026 | BB4: ="Travsix"&CHAR(RANDBETWEEN(65,90))&CHAR(RANDBETWEEN(65,90))&CHAR(RANDBETWEEN(65,90)) -> TravsixBTU | BC4: Last | BE4: =TEXT(DATE(YEAR(TODAY())-BD4,MONTH(TODAY()),DAY(TODAY())),"DD/MM/YYYY") -> 18/05/2026 | BF4: ="Travseven"&CHAR(RANDBETWEEN(65,90))&CHAR(RANDBETWEEN(65,90))&CHAR(RANDBETWEEN(65,90)) -> TravsevenDFC | BG4: Last | BI4: =TEXT(DATE(YEAR(TODAY())-BH4,MONTH(TODAY()),DAY(TODAY())),"DD/MM/YYYY") -> 18/05/2026 | BJ4: ="Traveight"&CHAR(RANDBETWEEN(65,90))&CHAR(RANDBETWEEN(65,90))&CHAR(RANDBETWEEN(65,90)) -> TraveightPSN | BK4: Last | BM4: =TEXT(DATE(YEAR(TODAY())-BL4,MONTH(TODAY()),DAY(TODAY())),"DD/MM/YYYY") -> 18/05/2026 | BN4: ="Travnine"&CHAR(RANDBETWEEN(65,90))&CHAR(RANDBETWEEN(65,90))&CHAR(RANDBETWEEN(65,90)) -> TravnineABW | BO4: Last | BQ4: =TEXT(DATE(YEAR(TODAY())-BP4,MONTH(TODAY()),DAY(TODAY())),"DD/MM/YYYY") -> 18/05/2026 | BT4: Y | BW4: YES | BX4: NO | BY4: YES | BZ4: NO | CA4: NO | CB4: NO | CC4: NO | CD4: Asthma | CE4: One | CF4: Yes | CG4: Chest infection | CH4: Yes | CI4: Yes | CJ4: One | CK4: No | CO4: International Comprehensive | CP4: 0 | CQ4: Y | CR4: N | CS4: N | CT4: Y | CU4: N | CV4: N | CW4: 0 | DM4: ="QATestFName"&CHAR(RANDBETWEEN(69,80))&CHAR(RANDBETWEEN(69,80))&CHAR(RANDBETWEEN(69,80))&RANDBETWEEN(111,999) -> QATestFNameOEF484 | DN4: ="QATestLName"&CHAR(RANDBETWEEN(69,80))&CHAR(RANDBETWEEN(69,80))&CHAR(RANDBETWEEN(69,80))&RANDBETWEEN(111,999) -> QATestLNameJLM172 | DO4: staging.emailstravelguard.com@aig.com | DP4: staging.emailstravelguard.com@aig.com | DQ4: 9876543210 | DR4: Test Address1 | DS4: Address2 | DT4: Test City | DU4: Victoria | DV4: 876543 | DW4: AU | DX4: QA Test | DY4: 032030 | DZ4: 737 | EA4: 5555341244441115 | EC4: =Global!$C$19&C4&"Staff_PDS.pdf" -> L:\Regression\Test Results\Temp_Results\AEM Regression\Qantas\UAT\Qantas StandAlone - Staff Daily Regression_2026-May-18-1215_23\Staff - QAStaff_PDS.pdf | ED4: =Global!$C$19&C4&"Staff_TMD.pdf" -> L:\Regression\Test Results\Temp_Results\AEM Regression\Qantas\UAT\Qantas StandAlone - Staff Daily Regression_2026-May-18-1215_23\Staff - QAStaff_TMD.pdf
A5: Y | B5: =B3&"/employee/home" -> https://qantas.uat.travelguard.com/employee/home | C5: Staff - UAT | E5: Annual Multi Trip | F5: ALBANIA | G5: ECUADOR | H5: NEW ZEALAND | I5: =VLOOKUP(Global!$B$2,Global!$E$1:$H$4,3,FALSE) -> https://api.uat.travelguard.com/policy/v4/ | J5: =VLOOKUP(Global!$B$2,Global!$E$1:$H$4,4,FALSE) -> https://agents.uat.travelguard.com/content/tg-agents/qantas/en/login.html | K5: M23WSADEB65Y5A6J | L5: Test Memo 07282023134349 | M5: 1253229296 | N5: test102024 | O5: EMC7 | Q5: N | R5: 1979970702 | S5: Loytest | T5: 1717 | V5: Mum | W5: 01 | X5: January | Y5: 2001 | Z5: 2020 | AA5: July | AB5: 2024 | AC5: =TEXT(TODAY()+1,"DD/MM/YYYY") -> 19/05/2026 | AD5: =TEXT(TODAY()+2,"DD/MM/YYYY") -> 20/05/2026 | AE5: 75 | AF5: =TEXT(DATE(YEAR(TODAY())-AE5,MONTH(TODAY()),DAY(TODAY())),"DD/MM/YYYY") -> 18/05/1951 | AG5: 2 | AH5: ="Travone"&CHAR(RANDBETWEEN(65,90))&CHAR(RANDBETWEEN(65,90))&CHAR(RANDBETWEEN(65,90)) -> TravoneKMZ | AI5: Test | AJ5: 35 | AK5: =TEXT(DATE(YEAR(TODAY())-AJ5,MONTH(TODAY()),DAY(TODAY())),"DD/MM/YYYY") -> 18/05/1991 | AL5: ="Travtwo"&CHAR(RANDBETWEEN(65,90))&CHAR(RANDBETWEEN(65,90))&CHAR(RANDBETWEEN(65,90)) -> TravtwoTVC | AM5: Test | AN5: 8 | AO5: =TEXT(DATE(YEAR(TODAY())-AN5,MONTH(TODAY()),DAY(TODAY())),"DD/MM/YYYY") -> 18/05/2018 | AP5: ="Travthree"&CHAR(RANDBETWEEN(65,90))&CHAR(RANDBETWEEN(65,90))&CHAR(RANDBETWEEN(65,90)) -> TravthreeACZ | AQ5: Test | AS5: =TEXT(DATE(YEAR(TODAY())-AR5,MONTH(TODAY()),DAY(TODAY())),"DD/MM/YYYY") -> 18/05/2026 | AT5: ="Travfour"&CHAR(RANDBETWEEN(65,90))&CHAR(RANDBETWEEN(65,90))&CHAR(RANDBETWEEN(65,90)) -> TravfourEQX | AU5: Last | AW5: =TEXT(DATE(YEAR(TODAY())-AV5,MONTH(TODAY()),DAY(TODAY())),"DD/MM/YYYY") -> 18/05/2026 | AX5: ="Travfive"&CHAR(RANDBETWEEN(65,90))&CHAR(RANDBETWEEN(65,90))&CHAR(RANDBETWEEN(65,90)) -> TravfiveLGR | AY5: Last | BA5: =TEXT(DATE(YEAR(TODAY())-AZ5,MONTH(TODAY()),DAY(TODAY())),"DD/MM/YYYY") -> 18/05/2026 | BB5: ="Travsix"&CHAR(RANDBETWEEN(65,90))&CHAR(RANDBETWEEN(65,90))&CHAR(RANDBETWEEN(65,90)) -> TravsixGIR | BC5: Last | BE5: =TEXT(DATE(YEAR(TODAY())-BD5,MONTH(TODAY()),DAY(TODAY())),"DD/MM/YYYY") -> 18/05/2026 | BF5: ="Travseven"&CHAR(RANDBETWEEN(65,90))&CHAR(RANDBETWEEN(65,90))&CHAR(RANDBETWEEN(65,90)) -> TravsevenOWR | BG5: Last | BI5: =TEXT(DATE(YEAR(TODAY())-BH5,MONTH(TODAY()),DAY(TODAY())),"DD/MM/YYYY") -> 18/05/2026 | BJ5: ="Traveight"&CHAR(RANDBETWEEN(65,90))&CHAR(RANDBETWEEN(65,90))&CHAR(RANDBETWEEN(65,90)) -> TraveightHSJ | BK5: Last | BM5: =TEXT(DATE(YEAR(TODAY())-BL5,MONTH(TODAY()),DAY(TODAY())),"DD/MM/YYYY") -> 18/05/2026 | BN5: ="Travnine"&CHAR(RANDBETWEEN(65,90))&CHAR(RANDBETWEEN(65,90))&CHAR(RANDBETWEEN(65,90)) -> TravnineUDD | BO5: Last | BQ5: =TEXT(DATE(YEAR(TODAY())-BP5,MONTH(TODAY()),DAY(TODAY())),"DD/MM/YYYY") -> 18/05/2026 | BT5: Y | BW5: YES | BX5: NO | BY5: YES | BZ5: NO | CA5: NO | CB5: NO | CC5: NO | CD5: Asthma | CE5: One | CF5: Yes | CG5: Chest infection | CH5: Yes | CI5: Yes | CJ5: One | CK5: No | CO5: Annual Multi Trip | CP5: 0 | CQ5: Yes | CR5: No | CS5: No | CT5: Yes | CU5: No | CV5: No | CW5: 0 | DM5: ="QATestFName"&CHAR(RANDBETWEEN(69,80))&CHAR(RANDBETWEEN(69,80))&CHAR(RANDBETWEEN(69,80))&RANDBETWEEN(111,999) -> QATestFNameEGO747 | DN5: ="QATestLName"&CHAR(RANDBETWEEN(69,80))&CHAR(RANDBETWEEN(69,80))&CHAR(RANDBETWEEN(69,80))&RANDBETWEEN(111,999) -> QATestLNamePOK414 | DO5: qa@travelguard.com | DP5: qa@travelguard.com | DQ5: 9876543210 | DR5: Test Address1 | DS5: Address2 | DT5: Test City | DU5: Victoria | DV5: 876543 | DW5: AU | DX5: QA Test | DY5: 032030 | DZ5: 737 | EA5: 5555341244441115 | EC5: =Global!$C$19&C5&"Staff_PDS.pdf" -> L:\Regression\Test Results\Temp_Results\AEM Regression\Qantas\UAT\Qantas StandAlone - Staff Daily Regression_2026-May-18-1215_23\Staff - UATStaff_PDS.pdf | ED5: =Global!$C$19&C5&"Staff_TMD.pdf" -> L:\Regression\Test Results\Temp_Results\AEM Regression\Qantas\UAT\Qantas StandAlone - Staff Daily Regression_2026-May-18-1215_23\Staff - UATStaff_TMD.pdf
R8: Alternative Users
R10: 2005276767 | S10: locked
R11: Flytest
R12: 1717
R14: 2005276874
R15: Lava
R16: 1717
R18: 2005276957
R19: Flytest
R20: 1717
R22: 2005277013
R23: Flytest
R24: 1717
R26: 1979970736
R27: 1979970702
R28: 1979970710

Sheet AgentStandAlone
A1: blnExecute | B1: Step_Number | C1: Step_Name | D1: Status | E1: Error_Check | F1: breakpoint | G1: Test_Case | H1: Page | I1: FindBy | J1: FindBy_Value | K1: Index | L1: Method | M1: Value | N1: Output_Property | O1: Ignore_not_existing_object | P1: isDisabled | Q1: Timeout | R1: Expected_Value | S1: Output_Value | T1: Exact_Match | U1: Contains | V1: Notes | W1: Start_Time | X1: End_Time | Y1: Duration
A2: Open Site - StandAlone
A3: Y | B3: =COUNTA($C$2:C3) -> 1 | C3: Launch Site | G3: DT_Scenario | H3: chrome | K3: 0 | L3: Open | M3: DT_StandAlone_URL
A4: N | B4: =COUNTA($C$2:C4) -> 2 | C4: Wait | G4: DT_Scenario | L4: Wait | M4: 10
A5: N | B5: =COUNTA($C$2:C5) -> 3 | C5: Zscaler Sign in Email | G5: DT_Scenario | I5: xpath | J5: //input[@id='okta-signin-username'] | K5: 0 | L5: Set | M5: DT_ZScalerUser | O5: Y | Q5: 5
A6: N | B6: =COUNTA($C$2:C6) -> 4 | C6: Zscaler Password | G6: DT_Scenario | I6: xpath | J6: //input[@id='okta-signin-password'] | K6: 0 | L6: Set | M6: DT_ZScalerPassword | O6: Y
A7: N | B7: =COUNTA($C$2:C7) -> 5 | C7: Click Sign in | G7: DT_Scenario | I7: xpath | J7: //input[@id='okta-signin-submit'] | K7: 0 | L7: Click | O7: Y
A8: N | B8: =COUNTA($C$2:C8) -> 6 | C8: Wait | G8: DT_Scenario | L8: Wait | M8: 5
A9: Qantas Standalone Purchase Path
A10: N | B10: =COUNTA($C$2:C10) -> 7 | C10: Click Login Icon | G10: DT_Scenario | I10: xpath | J10: //span[contains(.,'Log in')] | K10: 0 | L10: Click
A11: N | B11: =COUNTA($C$2:C11) -> 8 | C11: Wait | G11: DT_Scenario | L11: Wait | M11: 5
A12: N | B12: =COUNTA($C$2:C12) -> 9 | C12: Enter Membership Number | G12: DT_Scenario | I12: xpath | J12: //input[@name='memberId'] | K12: 0 | L12: Set | M12: DT_Login_MemberNo
A13: N | B13: =COUNTA($C$2:C13) -> 10 | C13: Enter Last Name | G13: DT_Scenario | I13: xpath | J13: //input[@name='lastName'] | K13: 0 | L13: Set | M13: DT_Login_Lastname
A14: N | B14: =COUNTA($C$2:C14) -> 11 | C14: Enter PIN | G14: DT_Scenario | I14: xpath | J14: //input[@type='password'] | K14: 0 | L14: Set | M14: DT_Login_PIN
A15: N | B15: =COUNTA($C$2:C15) -> 12 | C15: Click Login | G15: DT_Scenario | I15: xpath | J15: //button[contains(.,'LOG IN')] | K15: 0 | L15: Click
A16: N | B16: =COUNTA($C$2:C16) -> 13 | C16: Wait | G16: DT_Scenario | L16: Wait | M16: 3
A17: N | B17: =COUNTA($C$2:C17) -> 14 | C17: Enter Verification | G17: DT_Scenario | I17: xpath | J17: //input[@name='code'] | K17: 0 | L17: Set | M17: DT_OTP | O17: Y
A18: N | B18: =COUNTA($C$2:C18) -> 15 | C18: Click Verify | G18: DT_Scenario | I18: xpath | J18: //button[contains(.,'VERIFY')] | K18: 0 | L18: Click | O18: Y
A19: N | B19: =COUNTA($C$2:C19) -> 16 | C19: Wait | G19: DT_Scenario | L19: Wait | M19: 12
A20: GET A QUOTE
A21: Y | B21: =COUNTA($C$3:C21) -> 17 | C21: Select Trip Type | G21: DT_Scenario | I21: xpath | J21: ="//input[@value='"&M21&"']" -> //input[@value='DT_TripType'] | K21: 0 | L21: Tick | M21: DT_TripType
A22: Y | B22: =COUNTA($C$3:C22) -> 18 | C22: Wait | G22: DT_Scenario | L22: Wait | M22: 1
A23: Y | B23: =COUNTA($C$3:C23) -> 19 | C23: Click destination country textbox | G23: DT_Scenario | I23: xpath | J23: //input[contains(@placeholder,'Enter destinations (incl. any stopovers)')] | K23: =IF(M21="Single Trip","1","0") -> 0 | L23: Click
A24: Y | B24: =COUNTA($C$3:C24) -> 20 | C24: Select Country | G24: DT_Scenario | I24: xpath | J24: ="//a[contains(.,'"&M24&"')]" -> //a[contains(.,'DT_Country')] | K24: =K23 -> 0 | L24: Click | M24: DT_Country
A25: Y | B25: =COUNTA($C$3:C25) -> 21 | C25: Clear | G25: DT_Scenario | I25: xpath | J25: //input[@id='cmp-Input'] | K25: =IF(M21="Annual Multi Trip","0","1") -> 1 | L25: Click
A26: Y | B26: =COUNTA($C$3:C26) -> 22 | C26: Clear | G26: DT_Scenario | I26: xpath | K26: 0 | L26: sendkeys | M26: {TAB}
A27: Y | B27: =COUNTA($C$2:C27) -> 23 | C27: Check succeeding country if any | G27: DT_Scenario | I27: xpath | K27: 0 | L27: wait | M27: 1 | R27: DT_Country_2
A28: =IF(R27="NONE","N","Y") -> Y | B28: =COUNTA($C$2:C28) -> 24 | C28: Click destination country textbox | G28: DT_Scenario | I28: xpath | J28: //input[@class='inputField'] | K28: =IF(M21="Single Trip","1","0") -> 0 | L28: Click
A29: =A28 -> Y | B29: =COUNTA($C$2:C29) -> 25 | C29: Select Country | G29: DT_Scenario | I29: xpath | J29: ="//a[contains(.,'"&M29&"')]" -> //a[contains(.,'DT_Country_2')] | K29: =K28 -> 0 | L29: Click | M29: DT_Country_2
A30: =A29 -> Y | B30: =COUNTA($C$2:C30) -> 26 | C30: Clear | G30: DT_Scenario | I30: xpath | K30: 0 | L30: sendkeys | M30: {TAB}
A31: Y | B31: =COUNTA($C$2:C31) -> 27 | C31: Check succeeding country if any | G31: DT_Scenario | I31: xpath | K31: 0 | L31: wait | M31: 1 | R31: DT_Country_3
A32: =IF(R31="NONE","N","Y") -> Y | B32: =COUNTA($C$2:C32) -> 28 | C32: Click destination country textbox | G32: DT_Scenario | I32: xpath | J32: //input[@class='inputField'] | K32: =IF(M21="Single Trip","1","0") -> 0 | L32: Click
A33: =A32 -> Y | B33: =COUNTA($C$2:C33) -> 29 | C33: Select Country | G33: DT_Scenario | I33: xpath | J33: ="//a[contains(.,'"&M33&"')]" -> //a[contains(.,'DT_Country_3')] | K33: =K32 -> 0 | L33: Click | M33: DT_Country_3
A34: =A33 -> Y | B34: =COUNTA($C$2:C34) -> 30 | C34: Clear | G34: DT_Scenario | I34: xpath | K34: 0 | L34: sendkeys | M34: {TAB}
A35: Y | B35: =COUNTA($C$3:C35) -> 31 | C35: Enter Departure Date | G35: DT_Scenario | I35: xpath | J35: //input[contains(@name,'tripDepartureDate')] | K35: =IF(M21="Annual Multi Trip","0","0") -> 0 | L35: Set | M35: DT_DepartureDT
A36: =IF(M21="Annual Multi Trip","N","Y") -> Y | B36: =COUNTA($C$3:C36) -> 32 | C36: Enter Return Date | G36: DT_Scenario | I36: xpath | J36: //input[contains(@name,'tripReturnDate')] | K36: 0 | L36: Set | M36: DT_ReturnDT
A37: Y | B37: =COUNTA($C$3:C37) -> 33 | C37: Clear | G37: DT_Scenario | I37: xpath | K37: 0 | L37: sendkeys | M37: {TAB}
A38: Y | B38: =COUNTA($C$3:C38) -> 34 | C38: Enter Age of Primary Insured | G38: DT_Scenario | I38: xpath | J38: //input[@name='insuredAge'] | K38: 0 | L38: Set | M38: DT_PrimaryAge
A39: Y | B39: =COUNTA($C$3:C39) -> 35 | C39: Get number of additional travelers (if any) | G39: DT_Scenario | L39: Wait | M39: 1 | R39: DT_TravelersCount
A40: =IF($R$39>"0","Y","N") -> Y | B40: =COUNTA($C$3:C40) -> 36 | C40: Enter age of Traveler 1 | G40: DT_Scenario | I40: xpath | J40: //input[@name='insuredAge'] | K40: 1 | L40: Set | M40: DT_Age_TR1
...

Sheet PolicySearch
A1: blnExecute | B1: TCID | C1: TC_Name | D1: TestCondition | E1: WEBSERVICE_URL | F1: Async_GroupID | G1: Async_SequenceID | H1: JSON_FORMAT | I1: WEBSERVICE_METHOD | J1: ENVIRONMENT_PARAMETER | K1: XML_LOCATION | L1: XML_REQUESTFILE | M1: XML_RESPONSEFILE | N1: Username_IN | O1: Password_IN | P1: lastName_IN | Q1: policyNumber_IN | R1: DT_apiKey | S1: DT_bearerToken | T1: DT_partnerCode_IN | U1: contractNumber_IN | V1: aigContractId_OUT | W1: aigContractNumber_OUT | X1: contractNumber_OUT | Y1: errors_EXP | Z1: transactionStatus_EXP | AA1: errors_OUT | AB1: transactionStatus_OUT | AC1: errors_STATUS | AD1: successful_STATUS | AE1: PolicyStatus_EXP | AF1: PolicyStatus_OUT | AG1: MedScen01_EXP | AH1: MedScen01_OUT | AI1: MedScen02_EXP | AJ1: MedScen02_OUT | AK1: MedScen03_EXP | AL1: MedScen03_OUT | AM1: AgentEmail_EXP | AN1: AgentEmail_OUT | AO1: RES_STATUS_CD_STATUS | AP1: RES_STATUS_CD_EXP | AQ1: RES_STATUS_CD_OUT | AR1: REQUESTTIME_OUT | AS1: RESPONSETIME_OUT | AT1: ELAPSEDTIME_OUT | AU1: ERRORMESSAGE | AV1: sessionId_OUT | AW1: transactionId_OUT | AX1: message_EXP | AY1: message_OUT | AZ1: errorCode_EXP | BA1: errorCode_OUT
A3: Y | B3: =TEXT(COUNTA($A$3:$A3),"000") -> 001 | C3: Policy Search w EMC | D3: Policy Search w EMC | E3: =VLOOKUP(Global!$B$2,Global!$E$1:$G$4,3,FALSE)&Q3 -> https://api.uat.travelguard.com/policy/v4/0 | F3: 1 | G3: 1 | H3: Y | I3: GET | M3: ="TC"&B3&"_"&C3&".json" -> TC001_Policy Search w EMC.json | P3: =[5]AgentPortal_Params!T5 -> L | Q3: =AgentStandAlone_Params!E2 -> 0 | R3: RZEa1PtG45255Y1GoX6ULckorm2fX5tU | S3: Bearer eyJhbGciOiJIUzI1NiIsInR5cCI6IkpXVCJ9.eyJqdGkiOiIzODEwY2VkNy1jZmIxLTQyNWQtODY2Yy0xOTg1YzgyZWRiMzgiLCJzdWIiOiJJbnRlcm5ldCBVc2VyIiwidW5pcXVlX25hbWUiOiJJbnRlcm5ldCBVc2VyIiwiZW1haWwiOiJpbnRlcm5ldHVzZXJAYWlnLmNvbSIsInVpZCI6IjM4OSIsIkFwcFBlcm1pc3Npb25zIjoiW10iLCJDb3VudHJ5UGVybWlzc2lvbnMiOiJbXSIsIlBhcnRuZXJQZXJtaXNzaW9ucyI6IltdIiwiUGFydG5lckNvdW50cnlQZXJtaXNzaW9ucyI6IltdIiwiQ29udGFjdE9yZ2FuaXphdGlvbnMiOiJbXSIsIkFnZW50Um9sZXMiOiJbe1wiQXJjXCI6XCJcIixcIlJvbGVcIjpcIlwifV0iLCJuYmYiOjE2NDkzMzEwMDEsImV4cCI6MTk2NDk5MzQwMSwiaXNzIjoiaHR0cHM6Ly9saXRlLnRyYXZlbGd1YXJkLm5ldCIsImF1ZCI6IkFnZW50TGluayJ9.HDAvxPQsLypsRKtbQNXnabGZuRvefTtaNJn8H3ZnXfo | Z3: Success | AE3: Active | AG3: Cover not available | AM3: qapoweruser01@gmail.com | AP3: 200

Sheet AgentStandAlone_Params
A1: blnExecute | B1: DT_StandAlone_URL | C1: DT_AgentPortal_URL | D1: DT_Scenario | E1: DT_Policy_Out | F1: DT_Quote_Out | G1: DT_TripType | H1: DT_Country | I1: DT_Country_2 | J1: DT_Country_3 | K1: DT_Username_IN | L1: DT_Password_IN | M1: DT_Key | N1: DT_MemoText_IN | O1: DT_PolicyNumber_IN | P1: DT_LastName_IN | Q1: EMC Scenario | R1: Login Scenario | S1: DT_ValidateQFF | T1: DT_Login_MemberNo | U1: DT_Login_Lastname | V1: DT_Login_PIN | W1: DT_OTP | X1: DT_DepartureDT | Y1: DT_ReturnDT | Z1: DT_PrimaryAge | AA1: DT_MemDateofBirth | AB1: DT_TravelersCount | AC1: DT_MemFirstNameTR1 | AD1: DT_MemLastNameTR1 | AE1: DT_Age_TR1 | AF1: DT_MemDateofBirthTR1 | AG1: DT_MemFirstNameTR2 | AH1: DT_MemLastNameTR2 | AI1: DT_Age_TR2 | AJ1: DT_MemDateofBirthTR2 | AK1: DT_MemFirstNameTR3 | AL1: DT_MemLastNameTR3 | AM1: DT_Age_TR3 | AN1: DT_MemDateofBirthTR3 | AO1: DT_MemFirstNameTR4 | AP1: DT_MemLastNameTR4 | AQ1: DT_Age_TR4 | AR1: DT_MemDateofBirthTR4 | AS1: DT_MemFirstNameTR5 | AT1: DT_MemLastNameTR5 | AU1: DT_Age_TR5 | AV1: DT_MemDateofBirthTR5 | AW1: DT_MemFirstNameTR6 | AX1: DT_MemLastNameTR6 | AY1: DT_Age_TR6 | AZ1: DT_MemDateofBirthTR6 | BA1: DT_MemFirstNameTR7 | BB1: DT_MemLastNameTR7 | BC1: DT_Age_TR7 | BD1: DT_MemDateofBirthTR7 | BE1: DT_MemFirstNameTR8 | BF1: DT_MemLastNameTR8 | BG1: DT_Age_TR8 | BH1: DT_MemDateofBirthTR8 | BI1: DT_MemFirstNameTR9 | BJ1: DT_MemLastNameTR9 | BK1: DT_Age_TR9 | BL1: DT_MemDateofBirthTR9 | BM1: bln_EMC5 | BN1: bln_EMC6 | BO1: bln_EMC7 | BP1: bln_EMC8 | BQ1: bln_EMC9 | BR1: DT_EMCQ1 | BS1: DT_EMCQ2 | BT1: DT_EMCQ3 | BU1: DT_EMCQ4 | BV1: DT_EMCQ5 | BW1: DT_EMCQ6 | BX1: DT_EMCQ7 | BY1: DT_EMCQ8 | BZ1: DT_EMCQ9 | CA1: DT_EMCQ10 | CB1: DT_EMCQ11 | CC1: DT_EMCQ12 | CD1: DT_EMCQ13 | CE1: DT_EMCQ14 | CF1: DT_EMCQ15 | CG1: DT_MemberNum | CH1: DT_MemberLastNm | CI1: DT_MemberPIN | CJ1: DT_PolicyType | CK1: DT_BasePoints | CL1: DT_SnowSports | CM1: DT_SpecifiedItems | CN1: DT_Cruise | CO1: DT_SpecItemsCount | CP1: DT_SpecItem1 | CQ1: DT_SpecItemVal1 | CR1: DT_SpecItemDescr1 | CS1: DT_SpecItem2 | CT1: DT_SpecItemVal2 | CU1: DT_SpecItemDescr2 | CV1: DT_SpecItem3 | CW1: DT_SpecItemVal3 | CX1: DT_SpecItemDescr3 | CY1: DT_SpecItem4 | CZ1: DT_SpecItemVal4 | DA1: DT_SpecItemDescr4 | DB1: DT_SpecItem5 | DC1: DT_SpecItemVal5 | DD1: DT_SpecItemDescr5 | DE1: DT_MemFirstName | DF1: DT_MemLastName | DG1: DT_MemEmail | DH1: DT_MemConfirmEmail | DI1: DT_MemPhoneNumber | DJ1: DT_MemAddress1 | DK1: DT_MemAddress2 | DL1: DT_MemCity | DM1: DT_MemState | DN1: DT_MemPostalCode | DO1: DT_MemCountry | DP1: DT_MemCCName | DQ1: DT_MemCCExpDt | DR1: DT_MemCVV | DS1: DT_MemCCNumber | DT1: DT_ErrorMsg_Out | DU1: PDSSavePath | DV1: TMDSavePath
A2: Y | B2: =VLOOKUP(Global!$B$2,Global!$E$1:$F$4,2,FALSE) -> https://qantas.uat.travelguard.com | C2: =VLOOKUP(Global!$B$2,Global!$E$1:$H$4,4,FALSE) -> https://agents.uat.travelguard.com/content/tg-agents/qantas/en/login.html | D2: StandAlone Quote - Agent Purchase | G2: Single Trip | H2: ALBANIA | I2: ECUADOR | J2: NEW ZEALAND | K2: Qapoweruser01@gmail.com | L2: P@ssword01 | M2: CDJUOOD5RYKUGUUN | N2: Test Memo 07282023134349 | O2: 1253229296 | P2: test102024 | Q2: EMC7 | S2: N | T2: 2005277013 | U2: Flytest | V2: 1717 | W2: 123456 | X2: =TEXT(TODAY()+1,"DD/MM/YYYY") -> 19/05/2026 | Y2: =TEXT(TODAY()+8,"DD/MM/YYYY") -> 26/05/2026 | Z2: 35 | AA2: =TEXT(DATE(YEAR(TODAY())-Z2,MONTH(TODAY()),DAY(TODAY())),"DD/MM/YYYY") -> 18/05/1991 | AB2: 0 | AC2: ="Travone"&CHAR(RANDBETWEEN(65,90))&CHAR(RANDBETWEEN(65,90))&CHAR(RANDBETWEEN(65,90)) -> TravoneSHW | AD2: Test | AE2: 9 | AF2: =TEXT(DATE(YEAR(TODAY())-AE2,MONTH(TODAY()),DAY(TODAY())),"DD/MM/YYYY") -> 18/05/2017 | AG2: ="Travtwo"&CHAR(RANDBETWEEN(65,90))&CHAR(RANDBETWEEN(65,90))&CHAR(RANDBETWEEN(65,90)) -> TravtwoUMR | AH2: Test | AI2: 92 | AJ2: =TEXT(DATE(YEAR(TODAY())-AI2,MONTH(TODAY()),DAY(TODAY())),"DD/MM/YYYY") -> 18/05/1934 | AK2: ="Travthree"&CHAR(RANDBETWEEN(65,90))&CHAR(RANDBETWEEN(65,90))&CHAR(RANDBETWEEN(65,90)) -> TravthreeYKK | AL2: Test | AN2: =TEXT(DATE(YEAR(TODAY())-AM2,MONTH(TODAY()),DAY(TODAY())),"DD/MM/YYYY") -> 18/05/2026 | AO2: ="Travfour"&CHAR(RANDBETWEEN(65,90))&CHAR(RANDBETWEEN(65,90))&CHAR(RANDBETWEEN(65,90)) -> TravfourARW | AP2: Last | AR2: =TEXT(DATE(YEAR(TODAY())-AQ2,MONTH(TODAY()),DAY(TODAY())),"DD/MM/YYYY") -> 18/05/2026 | AS2: ="Travfive"&CHAR(RANDBETWEEN(65,90))&CHAR(RANDBETWEEN(65,90))&CHAR(RANDBETWEEN(65,90)) -> TravfiveOQW | AT2: Last | AV2: =TEXT(DATE(YEAR(TODAY())-AU2,MONTH(TODAY()),DAY(TODAY())),"DD/MM/YYYY") -> 18/05/2026 | AW2: ="Travsix"&CHAR(RANDBETWEEN(65,90))&CHAR(RANDBETWEEN(65,90))&CHAR(RANDBETWEEN(65,90)) -> TravsixHHK | AX2: Last | AZ2: =TEXT(DATE(YEAR(TODAY())-AY2,MONTH(TODAY()),DAY(TODAY())),"DD/MM/YYYY") -> 18/05/2026 | BA2: ="Travseven"&CHAR(RANDBETWEEN(65,90))&CHAR(RANDBETWEEN(65,90))&CHAR(RANDBETWEEN(65,90)) -> TravsevenXWE | BB2: Last | BD2: =TEXT(DATE(YEAR(TODAY())-BC2,MONTH(TODAY()),DAY(TODAY())),"DD/MM/YYYY") -> 18/05/2026 | BE2: ="Traveight"&CHAR(RANDBETWEEN(65,90))&CHAR(RANDBETWEEN(65,90))&CHAR(RANDBETWEEN(65,90)) -> TraveightYKL | BF2: Last | BH2: =TEXT(DATE(YEAR(TODAY())-BG2,MONTH(TODAY()),DAY(TODAY())),"DD/MM/YYYY") -> 18/05/2026 | BI2: ="Travnine"&CHAR(RANDBETWEEN(65,90))&CHAR(RANDBETWEEN(65,90))&CHAR(RANDBETWEEN(65,90)) -> TravnineJAI | BJ2: Last | BL2: =TEXT(DATE(YEAR(TODAY())-BK2,MONTH(TODAY()),DAY(TODAY())),"DD/MM/YYYY") -> 18/05/2026 | BO2: Y | BR2: YES | BS2: NO | BT2: YES | BU2: NO | BV2: NO | BW2: NO | BX2: NO | BY2: Asthma | BZ2: One | CA2: Yes | CB2: Chest infection | CC2: Yes | CD2: Yes | CE2: One | CF2: No | CJ2: International Comprehensive | CK2: =IF(CJ2="Australian Comprehensive",100,IF(CJ2="International Comprehensive",1700,IF(CJ2="Annual Multi Trip",7300,"invalid"))) -> 1700 | CL2: No | CM2: No | CN2: No | CO2: 5 | CP2: Sport & Leisure Equipment | CQ2: 1000 | CR2: SLE1 | CS2: Sport & Leisure Equipment | CT2: 1000 | CU2: SLE2 | CV2: Sport & Leisure Equipment | CW2: 3000 | CX2: SLE3 | CY2: Personal Computers | CZ2: 7000 | DA2: PC7000 | DB2: Other Luggage Item | DC2: 8000 | DD2: Luggage | DE2: ="QATestFName"&CHAR(RANDBETWEEN(69,80))&CHAR(RANDBETWEEN(69,80))&CHAR(RANDBETWEEN(69,80))&RANDBETWEEN(111,999) -> QATestFNameFJF250 | DF2: ="QATestLName"&CHAR(RANDBETWEEN(69,80))&CHAR(RANDBETWEEN(69,80))&CHAR(RANDBETWEEN(69,80))&RANDBETWEEN(111,999) -> QATestLNameEKL632 | DG2: qa@travelguard.com | DH2: qa@travelguard.com | DI2: 9876543210 | DJ2: Test Address1 | DK2: Address2 | DL2: Test City | DM2: Victoria | DN2: 876543 | DO2: AU | DP2: QA Test | DQ2: 032030 | DR2: 737 | DS2: 5555341244441115 | DU2: =Global!$C$19&D2&"Standalone_PDS.pdf" -> L:\Regression\Test Results\Temp_Results\AEM Regression\Qantas\UAT\Qantas StandAlone - Staff Daily Regression_2026-May-18-1215_23\StandAlone Quote - Agent PurchaseStandalone_PDS.pdf | DV2: =Global!$C$19&D2&"Standalone_TMD.pdf" -> L:\Regression\Test Results\Temp_Results\AEM Regression\Qantas\UAT\Qantas StandAlone - Staff Daily Regression_2026-May-18-1215_23\StandAlone Quote - Agent PurchaseStandalone_TMD.pdf

Sheet Qantas_AgentPortal
A1: blnExecute | B1: Step_Number | C1: Step_Name | D1: Status | E1: Error_Check | F1: breakpoint | G1: Test_Case | H1: Page | I1: FindBy | J1: FindBy_Value | K1: Index | L1: Method | M1: Value | N1: Output_Property | O1: Ignore_not_existing_object | P1: isDisabled | Q1: Timeout | R1: Expected_Value | S1: Output_Value | T1: Exact_Match | U1: Contains | V1: Notes | W1: Start_Time | X1: End_Time | Y1: Duration
A2: Login
A3: Y | B3: =COUNTA($C$3:C3) -> 1 | C3: Open Browser and Launch website | G3: DT_Scenario | H3: Chrome | L3: Open | M3: DT_URL
A4: Y | B4: =COUNTA($C$3:C4) -> 2 | C4: Enter username | G4: DT_Scenario | I4: xpath | J4: //input[@name='username'] | K4: 0 | L4: Set | M4: DT_Username_IN | Q4: 30
A5: Y | B5: =COUNTA($C$3:C5) -> 3 | C5: Click Next | G5: DT_Scenario | I5: xpath | J5: //input[@type='submit'] | K5: 0 | L5: Click
